Workbook

Sheet 표지

Sheet 자산목록
A1: 자산목록
A3: No. | B3: 호스트명 | C3: IP | D3: OS/SW | E3: 버전 | F3: 변경버전 | G3: 자산명/용도 | H3: 설치위치 | I3: 담당자 | J3: 구분
A5: U_001 | B5: idt-gov-jenkins | C5: 10.0.0.10 | D5: Rocky Linux | E5: 8.6 | F5: - | G5: CI/CD | H5: NAVER Cloud 공공기관용 | I5: 박영규 | J5: -
A6: U_002 | B6: igt-gov-bastion | C6: 10.0.2.10 | D6: Rocky Linux | E6: 8.6 | F6: - | G6: Bastion | H6: NAVER Cloud 공공기관용 | I6: 박영규 | J6: -
A7: U_003 | B7: idt-gov-ngs | C7: 10.0.1.10 | D7: centos | E7: 7.8 | F7: - | G7: 접근제어관리 | H7: NAVER Cloud 공공기관용 | I7: 박영규 | J7: -
A8: U_004 | B8: idt-gov-pool3-w-155j | C8: 10.0.3.11 | D8: Ubuntu | E8: 20.04 | F8: - | G8: work node | H8: NAVER Cloud 공공기관용 | I8: 박영규 | J8: -
A9: U_005 | B9: idt-gov-pool4-w-158h | C9: 10.0.3.12 | D9: Ubuntu | E9: 20.04 | F9: - | G9: work node | H9: NAVER Cloud 공공기관용 | I9: 박영규 | J9: -
A10: U_006 | B10: pcespg-web-admin-55845bc69b-nxztw | C10: 198.19.245.47 | D10: Debian GNU/Linux | E10: 12 | F10: - | G10: 관리자 웹서버. 관리자 웹페이지 | H10: NAVER Cloud 공공기관용 NKS | I10: 박영규 | J10: -
A11: U_007 | B11: pcespg-web-admin-55845bc69b-p86mk | C11: 198.19.245.47 | D11: Debian GNU/Linux | E11: 12 | G11: 관리자 웹서버. 관리자 웹페이지 | H11: NAVER Cloud 공공기관용 NKS | I11: 박영규 | J11: -
A12: U_008 | B12: pcespg-web-5674f488d5-nq9w5 | C12: 198.19.155.127 | D12: Debian GNU/Linux | E12: 12 | F12: - | G12: PCES 웹서버. Pces 웹페이지 | H12: NAVER Cloud 공공기관용 NKS | I12: 박영규 | J12: -
A13: U_009 | B13: pcespg-web-5674f488d5-h7zzl | C13: 198.19.155.127 | D13: Debian GNU/Linux | E13: 12 | G13: PCES 웹서버. Pces 웹페이지 | H13: NAVER Cloud 공공기관용 NKS | I13: 박영규 | J13: -
A14: U_010 | B14: pcespg-api-admin-74df64559f-5wgfk | C14: 198.19.150.60 | D14: Ubuntu | E14: 22.04.3 | F14: - | G14: 관리자 api 서버. 관리자 api | H14: NAVER Cloud 공공기관용 NKS | I14: 박영규 | J14: -
A15: U_011 | B15: pcespg-api-admin-74df64559f-rrwrl | C15: 198.19.150.60 | D15: Ubuntu | E15: 22.04.3 | G15: 관리자 api 서버. 관리자 api | H15: NAVER Cloud 공공기관용 NKS | I15: 박영규 | J15: -
A16: U_012 | B16: pcespg-api-biz-5749fc55dc-sj9mp | C16: 198.19.237.2 | D16: Ubuntu | E16: 22.04.3 | F16: - | G16: PCES api 서버. 업무 api | H16: NAVER Cloud 공공기관용 NKS | I16: 박영규 | J16: -
A17: U_013 | B17: pcespg-api-biz-5749fc55dc-g956g | C17: 198.19.237.2 | D17: Ubuntu | E17: 22.04.3 | G17: PCES api 서버. 업무 api | H17: NAVER Cloud 공공기관용 NKS | I17: 박영규 | J17: -
A18: U_014 | B18: pcespg-api-comm-796dfdd4bd-74zj4 | C18: 198.19.149.38 | D18: Ubuntu | E18: 22.04.3 | F18: - | G18: PCES api 서버. 공통 api | H18: NAVER Cloud 공공기관용 NKS | I18: 박영규 | J18: -
A19: U_015 | B19: pcespg-api-comm-796dfdd4bd-54kdc | C19: 198.19.149.38 | D19: Ubuntu | E19: 22.04.3 | G19: PCES api 서버. 공통 api | H19: NAVER Cloud 공공기관용 NKS | I19: 박영규 | J19: -
A20: U_016 | B20: pcespg-gw-5bc7bfb557-n9dbr | C20: 198.19.207.169 | D20: Ubuntu | E20: 22.04.3 | F20: - | G20: PCES 게이트웨이 서버. Api 게이트웨이 | H20: NAVER Cloud 공공기관용 NKS | I20: 박영규 | J20: -
A21: U_017 | B21: pcespg-gw-5bc7bfb557-fb6g9 | C21: 198.19.207.169 | D21: Ubuntu | E21: 22.04.3 | G21: PCES 게이트웨이 서버. Api 게이트웨이 | H21: NAVER Cloud 공공기관용 NKS | I21: 박영규 | J21: -
A22: U_018 | B22: gaia | C22: 198.19.178.189 | D22: Ubuntu | E22: 22.04.3 | F22: - | G22: GAIA 서버. 가이아 서비스 | H22: NAVER Cloud 공공기관용 NKS | I22: 박영규 | J22: -

Sheet ChkList
A1: Check List | E1: 분류 Code
E2: U
A3: 점검항목
A4: 분류 | C4: 점검항목 | D4: 중요도
A5: =$E$2&"1" -> U1 | B5: 계정 관리
B6: U-01 | C6: root 계정 원격 접속 제한 | D6: H | G6: [Telnet] 1. “/etc/securetty” 파일에서 pts/0 ~ pts/x 설정 제거 또는, 주석 처리 [SSH] 1. vi 편집기를 이용하여 /etc/ssh/sshd_config 파일을 연 후 # vi /etc/ssh/sshd_config 2. 아래와 같이 설정 변경 PermitRootLogin no
B7: U-02 | C7: 패스워드 복잡성 설정 | D7: H | G7: [CentOS 7이상] # vi /etc/pam.d/system-auth password requisite pam_pwquality.so try_first_pass enforce_for_root retry=5 type= minlen=9 lcredit=-1 ucredit=-1 dcredit=-1 ocredit=-1 [CentOS 6이하] # vi /etc/pam.d/system-auth password requisite pam_cracklib.so try_first_pass enforce_for_root retry=5 type= minlen=9 lcredit=-1 ucredit=-1 dcredit=-1 ocredit=-1 [Ubuntu, Debian] 1. libpam-pwquality 설치 # apt -y install libpam-pwquality 2. vi 편집기를 이용하여 설정 파일을 연 후 # vi /etc/pam.d/common-password 3. pam_pwquality.so 부분을 아래와 같이 설정(예시) password requisite pam_pwquality.so enforce_for_root retry=3 minlen=9 dcredit=-1 ucredit=-1 lcredit=-1 ocredit=-1 ※패스워드 복잡성 설정은 Debian 계열의 경우 common-password 파일 또는 pwquality.conf 파일, RedHat 계열의 경우 system-auth 파일 또는 pwquality.conf 파일 둘 중 한 곳에만 적용하면 되며, enforce_for_root 설정은 system-auth 파일에 적용해야 함 ***설정 시 모듈이 있는지 확인 필요*** [일반적으로 권장하는 패스워드 설정] 1. 패스워드의 길이는 최소 9자 이상으로 설정 2. 영문(대문자, 소문자), 숫자, 특수문자를 혼합하여 패스워드 설정 3. 패스워드는 주기적으로 변경하고, 재사용 금지 4. 사전에 있는 단어나 누구나 유추 가능한 간단한 패스워드 사용 금지
B8: U-03 | C8: 계정 잠금 임계값 설정 | D8: H | G8: [CentOS] # vi /etc/pam.d/system-auth (*첫번째 단락 2번째줄) auth required pam_tally2.so deny=5 no_magic_root (*두번째 단락 2번째줄) account required pam_tally2.so # vi /etc/pam.d/password-auth (*첫번째 단락 2번째줄) auth required pam_tally2.so deny=5 onerr=fail (*두번째 단락 2번째줄) account required pam_tally2.so [Ubuntu] # vi /etc/pam.d/common-auth (*첫번째 단락 1번째줄) auth required pam_tally2.so deny=5
B9: U-04 | C9: 패스워드 최대 사용 기간 설정 | D9: M | G9: (User 생성시 적용) # vi /etc/login.defs PASS_MAX_DAYS 90 (현재 User의 최대 사용기간 적용) chage –M 90 <계정명>
B10: U-05 | C10: 패스워드 파일 보호 | D10: H | G10: 1. 쉐도우 패스워드 정책 적용 방법 # pwconv 2. 일반 패스워드 정책 적용 방법 #pwunconv
A11: =$E$2&"2" -> U2 | B11: 파일 및 디렉토리 관리
B12: U-06 | C12: root 홈, 패스 디렉터리 권한 및 패스 설정 | D12: H | G12: 1. vi 편집기를 이용하여 root 계정의 설정파일(~/.profile 과 /etc/profile)을 연 후 # vi /etc/profile 2. 아래와 같이 수정 (수정 전) PATH=.:$PATH:$HOME/bin (수정 후) PATH=$PATH:$HOME/bin
B13: U-07 | C13: 파일 및 디렉터리 소유자 설정 | D13: H | G13: 1. 소유자가 존재하지 않는 파일이나 디렉터리가 불필요한 경우 rm 명령으로 삭제 # rm <file_name> # rm <directory_name> ※ 삭제할 파일명 또는, 디렉터리명 입력 2. 필요한 경우 chown 명령으로 소유자 및 그룹 변경 chown <user_name> <file_name>
B14: U-08 | C14: /etc/passwd 파일 소유자 및 권한 설정 | D14: H | G14: 1. /etc/passwd 파일의 퍼미션을 644(또는 444)로, 소유자를 root로 변경 # chmod 644 /etc/passwd # chown root /etc/passwd
B15: U-09 | C15: /etc/shadow 파일 소유자 및 권한 설정 | D15: H | G15: 1. /etc/shadow 파일의 퍼미션을 600(또는 400)로, 소유자를 root로 변경 # chmod 600 /etc/shadow # chown root /etc/shadow
B16: U-10 | C16: /etc/hosts 파일 소유자 및 권한 설정 | D16: H | G16: 1. /etc/hosts 파일의 퍼미션을 644로, 소유자를 root로 변경 # chmod 644 /etc/hosts # chown root /etc/hosts
B17: U-11 | C17: /etc/(x)inetd.conf 파일 소유자 및 권한 설정 | D17: H | G17: 1. /etc/xinetd.conf 파일의 퍼미션과 소유자를 확인 # ls -l /etc/xinetd.conf -rw-------. 1 root root 1001 2013-10-07 10:34 /etc/xinetd.conf
B18: U-12 | C18: /etc/syslog.conf 파일 소유자 및 권한 설정 | D18: H | G18: 1. /etc/rsyslog.conf 파일의 퍼미션을 644로, 소유자를 root로 변경 # chmod 644 /etc/ rsyslog.conf # chown root /etc/ rsyslog.conf
B19: U-13 | C19: /etc/services 파일 소유자 및 권한 설정 | D19: H | G19: 1. /etc/services 파일의 퍼미션을 644로, 소유자를 root로 변경 # chmod 644 /etc/services # chown root /etc/services
B20: U-14 | C20: SUID, SGID, Sticky bit 설정 파일 점검 | D20: H | G20: 1. 검색된 파일 중 불필요한 파일 제거 및 권한 변경 예시 #chmod –s <file_name> #rm –rf <file_name>
B21: U-15 | C21: 사용자, 시스템 시작파일 및 환경파일 소유자 및 권한 설정 | D21: H | G21: 1. 소유자 변경 방법 #chown <user_name> <file_name> 2. 일반 사용자 쓰기 권한 제거 방법 #chmod o-w <file_name>
B22: U-16 | C22: world writable 파일 점검 | D22: H | G22: 1. 검색된 파일 중 불필요한 파일 제거 및 권한 변경 #chmod o-w <file_name> #rm –rf <world-writable 파일명>
B23: U-17 | C23: $HOME/.rhosts, hosts.equiv 사용 금지 | D23: H | G23: [.rhosts, hosts.equiv 파일 미사용 시] 1. .rhosts, hosts.equiv 파일 삭제 # rm -f [삭제 할 파일 및 디렉터리 경로] # rm -f $HOME/.rhosts 또는 or /etc/ hosts.equiv [.rhosts, hosts.equiv 파일 사용 시] 1. “/etc/hosts.equiv” 및 “$HOME/.rhosts” 파일의 소유자를 root 또는, 해당 계정으로 변경 # chown root /etc/hosts.equiv # chown [계정 명] $HOME/.rhosts 2. “/etc/hosts.equiv” 및 “$HOME/.rhosts” 파일의 퍼미션을 600 이하로 변경 # chmod 600 /etc/hosts.equiv # chmod 600 $HOME/.rhosts 3. “/etc/hosts.equiv” 및 “$HOME/.rhosts” 파일에서 “+”를 제거하고 허용 호스트 및 계정 등록 # vi /etc/hosts.equiv (or $HOME/.rhosts)
... B25: U-19 | C25: cron 파일 소유자 및 권한 설정 | D25: H | G25: 1. “/etc/cron.allow” 및 “/etc/cron.deny” 파일의 소유자 및 권한 변경 # chown root /etc/cron.allow # chmod 644 /etc/cron.allow # chown root /etc/cron.deny # chmod 644 /etc/cron.deny
A26: =$E$2&"3" -> U3 | B26: 서비스 관리
B27: U-20 | C27: Finger 서비스 비활성화 | D27: H | G27: 1. “/etc/xinetd.d/finger” 파일에서 서비스 비활성화 여부 확인 # cat /etc/xinetd.d/finger | grep disable disable = no
B28: U-21 | C28: Anonymous FTP 비활성화 | D28: H | G28: [Default FTP를 사용하는 경우] 1. ftp 계정 삭제 # userdel ftp //Linux, HP-UX, Solaris에서 ftp 계정 삭제 # rmuser ftp //AIX에서 ftp 계정 삭제 [proftpd 를 사용하는 경우] 1. proftpd.conf 파일에서 <Anonymous ~ ftp> 부분의 UserAlias 항목 주석("#") 처리 # cat etc/proftpd/proftpd.conf #UserAlias anonymous ftp [vsftpd 를 사용하는 경우] 1. vsftpd.conf 파일에서 anonymous_enable 값을 No 로 설정 # vi etc/vsftpd/vsftpd.conf anonymous_enalble = No
B29: U-22 | C29: r 계열 서비스 비활성화 | D29: H | G29: 1. vi 편집기를 이용하여 “/etc/xinetd.d/” 디렉터리 내 rlogin, rsh, rexec 파일을 연 후 2. 아래와 같이 설정 (disable = yes 설정) - /etc/xinetd.d/rlogin 파일 - /etc/xinetd.d/rsh 파일 - /etc/xinetd.d/rexec 파일 service rlogin { … disable = yes }
B30: U-23 | C30: DoS 공격에 취약한 서비스 비활성화 | D30: H | G30: 1. vi 편집기를 이용하여 “/etc/xinetd.d/” 디렉터리 내 echo, discard, daytime, chargen 파일을 연 후 2. 아래와 같이 설정 (disable = yes 설정) - /etc/xinetd.d/echo 파일 - /etc/xinetd.d/discard 파일 - /etc/xinetd.d/daytime 파일 - /etc/xinetd.d/chargen 파일 service echo { … disable = yes }
B31: U-24 | C31: NFS 서비스 비활성화 | D31: H | G31: 1. NFS 데몬(nfsd)을 중지 # ps -ef | grep nfsd root 3809 3721 0 08:44:40 ? 0:00 /usr/lib/nfs/nfsd # kill –9 3809
B32: U-25 | C32: NFS 접근통제 | D32: H | G32: 1. everyone 마운트 제거 # umount "파일시스템 이름" 2. /etc/exports 파일에서 접근 통제 설정 # vi /etc/exports (예) /data 172.27.0.0/16(rw,no_root_squash)
B33: U-26 | C33: automountd 제거 | D33: H | G33: 1. automountd서비스 데몬 실행 중지 # ps -ef | grep auto root 650 1 0 9월 07 ? 0:00 /usr/lib/autofs/automountd # kill –9 650 2. 시스템 재시작시 automount 가 시작되지 않도록 설정 <방법1> 부팅스크립트에서 automountd 제거 # chkconfig --level 0123456 autofs off <방법2> 아래와 같이 파일경로 확인 후 파일명 변경 (예) # mv /etc/rc2.d/S28autofs /etc/rc2.d/S28autofs.orig
B34: U-27 | C34: RPC 서비스 확인 | D34: H | G34: 1. vi 편집기를 이용하여 “/etc/xinetd.d/” 디렉터리 내의 불필요한 RPC 서비스 파일을 연 후 2. 아래와 같이 설정 (disable = yes 설정) service finger { disable = yes … 이하 생략 … }
B35: U-28 | C35: NIS, NIS+ 점검 | D35: H | G35: 1. NFS 서비스 데몬 중지 #kill -9 [PID]
B36: U-29 | C36: tftp, talk 서비스 비활성화 | D36: H | G36: 1. vi 편집기를 이용하여 “/etc/xinetd.d/” 디렉터리 내 tftp, talk, ntalk 파일을 연 후 2. 아래와 같이 설정 (disable = yes 설정) - /etc/xinetd.d/tftp 파일 - /etc/xinetd.d/talk 파일 - /etc/xinetd.d/ntalk 파일 service tftp { … 생략 … disable = yes }
B37: U-30 | C37: Sendmail 버전 점검 | D37: H | G37: [Sendmail을 사용하지 않을 경우] 1. 필요하지 않을 경우 Sendmail 데몬 중지 # ps -ef | grep sendmail root 536638 163960 0 Jul 03 - 2:34 sendmail: accepting connections # kill -9 536638 # stopsrc -s sendmail // AIX에서 Sendmail 중지 명령어 [시스템 재시작시 Sendmail이 구동되지 않도록 OS별로 아래와 같이 설정] <방법1> 부팅스크립트에서 Sendmail 제거 # chkconfig sendmail off //모던 런레벨에서 Sendmail 서비스 중지 # chkconfig --level 2345 sendmail off //런레벨 2~5에서 Sendmail 서비스 중지 <방법2> Sendmail 구동 스크립트 파일명 변경 # ls -al /etc/rc*.d/* | grep sendmail //파일 위치 검색 #mv /etc/rc2.d/S88sendmail /etc/rc2.d/S88sendmail.orig //파일명 변경
B38: U-31 | C38: 스팸 메일 릴레이 제한 | D38: H | G38: 1. vi 편집기를 이용하여 sendmail.cf 설정파일을 연 후 2. 아래와 같이 주석 제거 (수정 전) #R$* $#error $@ 5.7.1 $: "550 Relaying denied" (수정 후) R$* $#error $@ 5.7.1 $: "550 Relaying denied" 3. 특정 IP, domain, Email Address 및 네트워크에 대한 sendmail 접근 제한 확인 #vi /etc/mail/access
... B41: U-34 | C41: DNS ZoneTransfer 설정 | D41: H | G41: 1. 특정 서버의 Zone Transfer 지정 # vi /etc/named.conf Options { allow-transfer{10.10.10.111; 10.10.10.112;}; }; 2. 특정 도메인의 Zone에 대해서 제한할 경우에는 다음과 같이 설정 # vi /etc/named.conf zone "xxx.co.kr" { Type master ; File "db.xxx.co.kr"; allow-transfer{10.10.10.111; 10.10.10.112;}; }
A42: =$E$2&"4" -> U4 | B42: 패치 및 로그관리
B43: U-35 | C43: 최신 보안패치 및 벤더 권고사항 적용 | D43: H | G43: ※ 설정 기준 권고 (또는 정책기준) 1. 보안 취약점이 발표되면 시스템 영향도를 평가하고, 긴급 대응책 및 중장기 대응책을 마련하여 계획과 허가에 의해 대응하는 것이 좋다. 2. 패치를 수행할 시 시스템의 영향도에 따라 패치를 차등 수행하도록 한다. 3. 시스템 운영에 영향을 주지 않는 범위 내에서 주기적으로 패치를 수행할 것을 권고함
...

Sheet 통계
A1: 영역별/장비별 보안수준 통계
A3: 영역별 보안수준
A4: 분류 | E4: 점검 결과 | J4: 중요도점수
E5: 전체항목 | F5: 점검항목 | G5: 양호 | H5: 취약 | I5: 해당없음 | J5: 전체점수 | K5: 평가점수 | L5: 보안수준
A6: U1 | B6: =VLOOKUP($A6,ChkList!$A$5:$B$44,2,FALSE) -> 계정 관리 | E6: =SUMIF('항목별 통계'!$B:$B,$A6&"*",'항목별 통계'!$F:$F) -> 90 | F6: =E6-I6 -> 90 | G6: =SUMIF('항목별 통계'!$B:$B,$A6&"*",'항목별 통계'!$G:$G) -> 32 | H6: =SUMIF('항목별 통계'!$B:$B,$A6&"*",'항목별 통계'!$H:$H) -> 58 | I6: =SUMIF('항목별 통계'!$B:$B,$A6&"*",'항목별 통계'!$I:$I) -> 0 | J6: =SUMIF('항목별 통계'!$B:$B,$A6&"*",'항목별 통계'!$J:$J) -> 252 | K6: =SUMIF('항목별 통계'!$B:$B,$A6&"*",'항목별 통계'!$K:$K) -> 93 | L6: =IFERROR(K6/J6,0) -> 0.36904762
A7: U2 | B7: =VLOOKUP($A7,ChkList!$A$5:$B$44,2,FALSE) -> 파일 및 디렉토리 관리 | E7: =SUMIF('항목별 통계'!$B:$B,$A7&"*",'항목별 통계'!$F:$F) -> 252 | F7: =E7-I7 -> 252 | G7: =SUMIF('항목별 통계'!$B:$B,$A7&"*",'항목별 통계'!$G:$G) -> 219 | H7: =SUMIF('항목별 통계'!$B:$B,$A7&"*",'항목별 통계'!$H:$H) -> 33 | I7: =SUMIF('항목별 통계'!$B:$B,$A7&"*",'항목별 통계'!$I:$I) -> 0 | J7: =SUMIF('항목별 통계'!$B:$B,$A7&"*",'항목별 통계'!$J:$J) -> 756 | K7: =SUMIF('항목별 통계'!$B:$B,$A7&"*",'항목별 통계'!$K:$K) -> 657 | L7: =IFERROR(K7/J7,0) -> 0.86904762
A8: U3 | B8: =VLOOKUP($A8,ChkList!$A$5:$B$44,2,FALSE) -> 서비스 관리 | E8: =SUMIF('항목별 통계'!$B:$B,$A8&"*",'항목별 통계'!$F:$F) -> 270 | F8: =E8-I8 -> 270 | G8: =SUMIF('항목별 통계'!$B:$B,$A8&"*",'항목별 통계'!$G:$G) -> 269 | H8: =SUMIF('항목별 통계'!$B:$B,$A8&"*",'항목별 통계'!$H:$H) -> 1 | I8: =SUMIF('항목별 통계'!$B:$B,$A8&"*",'항목별 통계'!$I:$I) -> 0 | J8: =SUMIF('항목별 통계'!$B:$B,$A8&"*",'항목별 통계'!$J:$J) -> 810 | K8: =SUMIF('항목별 통계'!$B:$B,$A8&"*",'항목별 통계'!$K:$K) -> 807 | L8: =IFERROR(K8/J8,0) -> 0.9962963
A9: U4 | B9: =VLOOKUP($A9,ChkList!$A$5:$B$44,2,FALSE) -> 패치 및 로그관리 | E9: =SUMIF('항목별 통계'!$B:$B,$A9&"*",'항목별 통계'!$F:$F) -> 36 | F9: =E9-I9 -> 36 | G9: =SUMIF('항목별 통계'!$B:$B,$A9&"*",'항목별 통계'!$G:$G) -> 0 | H9: =SUMIF('항목별 통계'!$B:$B,$A9&"*",'항목별 통계'!$H:$H) -> 36 | I9: =SUMIF('항목별 통계'!$B:$B,$A9&"*",'항목별 통계'!$I:$I) -> 0 | J9: =SUMIF('항목별 통계'!$B:$B,$A9&"*",'항목별 통계'!$J:$J) -> 108 | K9: =SUMIF('항목별 통계'!$B:$B,$A9&"*",'항목별 통계'!$K:$K) -> 0 | L9: =IFERROR(K9/J9,0) -> 0
B10: 계 | E10: =SUM(E6:E9) -> 648 | F10: =SUM(F6:F9) -> 648 | G10: =SUM(G6:G9) -> 520 | H10: =SUM(H6:H9) -> 128 | I10: =SUM(I6:I9) -> 0 | J10: =SUM(J6:J9) -> 1926 | K10: =SUM(K6:K9) -> 1557 | L10: =IFERROR(K10/J10, 0) -> 0.80841121
A38: 장비별 보안수준
A39: 장비 구분 | E39: 점검 결과 | J39: 중요도점수
E40: 전체항목 | F40: 점검항목 | G40: 양호 | H40: 취약 | I40: 해당없음 | J40: 전체점수 | K40: 평가점수 | L40: 보안수준
A41: =IFERROR(자산목록!$A5,"-") -> U_001 | C41: =IFERROR(VLOOKUP($A41,자산목록!$A$1:$H$854,2,FALSE),"-") -> idt-gov-jenkins | E41: =IFERROR(INDIRECT(ADDRESS(16, 5, 1,TRUE,$A41)),0) -> 36 | F41: =IFERROR(INDIRECT(ADDRESS(16,6, 1,TRUE,$A41)),0) -> 36 | G41: =IFERROR(INDIRECT(ADDRESS(16,7, 1,TRUE,$A41)),0) -> 32 | H41: =F41-G41 -> 4 | I41: =E41-F41 -> 0 | J41: =IFERROR(INDIRECT(ADDRESS(16,8, 1,TRUE,$A41)),0) -> 107 | K41: =IFERROR(INDIRECT(ADDRESS(16,9, 1,TRUE,$A41)),0) -> 95 | L41: =IFERROR(INDIRECT(ADDRESS(16,10, 1,TRUE,$A41)),0) -> 0.88785047
A42: =IFERROR(자산목록!$A6,"-") -> U_002 | C42: =IFERROR(VLOOKUP($A42,자산목록!$A$1:$H$854,2,FALSE),"-") -> igt-gov-bastion | E42: =IFERROR(INDIRECT(ADDRESS(16, 5, 1,TRUE,$A42)),0) -> 36 | F42: =IFERROR(INDIRECT(ADDRESS(16,6, 1,TRUE,$A42)),0) -> 36 | G42: =IFERROR(INDIRECT(ADDRESS(16,7, 1,TRUE,$A42)),0) -> 32 | H42: =F42-G42 -> 4 | I42: =E42-F42 -> 0 | J42: =IFERROR(INDIRECT(ADDRESS(16,8, 1,TRUE,$A42)),0) -> 107 | K42: =IFERROR(INDIRECT(ADDRESS(16,9, 1,TRUE,$A42)),0) -> 95 | L42: =IFERROR(INDIRECT(ADDRESS(16,10, 1,TRUE,$A42)),0) -> 0.88785047
A43: =IFERROR(자산목록!$A7,"-") -> U_003 | C43: =IFERROR(VLOOKUP($A43,자산목록!$A$1:$H$854,2,FALSE),"-") -> idt-gov-ngs | E43: =IFERROR(INDIRECT(ADDRESS(16, 5, 1,TRUE,$A43)),0) -> 36 | F43: =IFERROR(INDIRECT(ADDRESS(16,6, 1,TRUE,$A43)),0) -> 36 | G43: =IFERROR(INDIRECT(ADDRESS(16,7, 1,TRUE,$A43)),0) -> 32 | H43: =F43-G43 -> 4 | I43: =E43-F43 -> 0 | J43: =IFERROR(INDIRECT(ADDRESS(16,8, 1,TRUE,$A43)),0) -> 107 | K43: =IFERROR(INDIRECT(ADDRESS(16,9, 1,TRUE,$A43)),0) -> 95 | L43: =IFERROR(INDIRECT(ADDRESS(16,10, 1,TRUE,$A43)),0) -> 0.88785047
A44: =IFERROR(자산목록!$A8,"-") -> U_004 | C44: =IFERROR(VLOOKUP($A44,자산목록!$A$1:$H$854,2,FALSE),"-") -> idt-gov-pool3-w-155j | E44: =IFERROR(INDIRECT(ADDRESS(16, 5, 1,TRUE,$A44)),0) -> 36 | F44: =IFERROR(INDIRECT(ADDRESS(16,6, 1,TRUE,$A44)),0) -> 36 | G44: =IFERROR(INDIRECT(ADDRESS(16,7, 1,TRUE,$A44)),0) -> 30 | H44: =F44-G44 -> 6 | I44: =E44-F44 -> 0 | J44: =IFERROR(INDIRECT(ADDRESS(16,8, 1,TRUE,$A44)),0) -> 107 | K44: =IFERROR(INDIRECT(ADDRESS(16,9, 1,TRUE,$A44)),0) -> 90 | L44: =IFERROR(INDIRECT(ADDRESS(16,10, 1,TRUE,$A44)),0) -> 0.8411215
A45: =IFERROR(자산목록!$A9,"-") -> U_005 | C45: =IFERROR(VLOOKUP($A45,자산목록!$A$1:$H$854,2,FALSE),"-") -> idt-gov-pool4-w-158h | E45: =IFERROR(INDIRECT(ADDRESS(16, 5, 1,TRUE,$A45)),0) -> 36 | F45: =IFERROR(INDIRECT(ADDRESS(16,6, 1,TRUE,$A45)),0) -> 36 | G45: =IFERROR(INDIRECT(ADDRESS(16,7, 1,TRUE,$A45)),0) -> 30 | H45: =F45-G45 -> 6 | I45: =E45-F45 -> 0 | J45: =IFERROR(INDIRECT(ADDRESS(16,8, 1,TRUE,$A45)),0) -> 107 | K45: =IFERROR(INDIRECT(ADDRESS(16,9, 1,TRUE,$A45)),0) -> 90 | L45: =IFERROR(INDIRECT(ADDRESS(16,10, 1,TRUE,$A45)),0) -> 0.8411215
A46: =IFERROR(자산목록!$A10,"-") -> U_006 | C46: =IFERROR(VLOOKUP($A46,자산목록!$A$1:$H$854,2,FALSE),"-") -> pcespg-web-admin-55845bc69b-nxztw | E46: =IFERROR(INDIRECT(ADDRESS(16, 5, 1,TRUE,$A46)),0) -> 36 | F46: =IFERROR(INDIRECT(ADDRESS(16,6, 1,TRUE,$A46)),0) -> 36 | G46: =IFERROR(INDIRECT(ADDRESS(16,7, 1,TRUE,$A46)),0) -> 28 | H46: =F46-G46 -> 8 | I46: =E46-F46 -> 0 | J46: =IFERROR(INDIRECT(ADDRESS(16,8, 1,TRUE,$A46)),0) -> 107 | K46: =IFERROR(INDIRECT(ADDRESS(16,9, 1,TRUE,$A46)),0) -> 84 | L46: =IFERROR(INDIRECT(ADDRESS(16,10, 1,TRUE,$A46)),0) -> 0.78504673
A47: =IFERROR(자산목록!$A11,"-") -> U_007 | C47: =IFERROR(VLOOKUP($A47,자산목록!$A$1:$H$854,2,FALSE),"-") -> pcespg-web-admin-55845bc69b-p86mk | E47: =IFERROR(INDIRECT(ADDRESS(16, 5, 1,TRUE,$A47)),0) -> 36 | F47: =IFERROR(INDIRECT(ADDRESS(16,6, 1,TRUE,$A47)),0) -> 36 | G47: =IFERROR(INDIRECT(ADDRESS(16,7, 1,TRUE,$A47)),0) -> 28 | H47: =F47-G47 -> 8 | I47: =E47-F47 -> 0 | J47: =IFERROR(INDIRECT(ADDRESS(16,8, 1,TRUE,$A47)),0) -> 107 | K47: =IFERROR(INDIRECT(ADDRESS(16,9, 1,TRUE,$A47)),0) -> 84 | L47: =IFERROR(INDIRECT(ADDRESS(16,10, 1,TRUE,$A47)),0) -> 0.78504673
A48: =IFERROR(자산목록!$A12,"-") -> U_008 | C48: =IFERROR(VLOOKUP($A48,자산목록!$A$1:$H$854,2,FALSE),"-") -> pcespg-web-5674f488d5-nq9w5 | E48: =IFERROR(INDIRECT(ADDRESS(16, 5, 1,TRUE,$A48)),0) -> 36 | F48: =IFERROR(INDIRECT(ADDRESS(16,6, 1,TRUE,$A48)),0) -> 36 | G48: =IFERROR(INDIRECT(ADDRESS(16,7, 1,TRUE,$A48)),0) -> 28 | H48: =F48-G48 -> 8 | I48: =E48-F48 -> 0 | J48: =IFERROR(INDIRECT(ADDRESS(16,8, 1,TRUE,$A48)),0) -> 107 | K48: =IFERROR(INDIRECT(ADDRESS(16,9, 1,TRUE,$A48)),0) -> 84 | L48: =IFERROR(INDIRECT(ADDRESS(16,10, 1,TRUE,$A48)),0) -> 0.78504673
A49: =IFERROR(자산목록!$A13,"-") -> U_009 | C49: =IFERROR(VLOOKUP($A49,자산목록!$A$1:$H$854,2,FALSE),"-") -> pcespg-web-5674f488d5-h7zzl | E49: =IFERROR(INDIRECT(ADDRESS(16, 5, 1,TRUE,$A49)),0) -> 36 | F49: =IFERROR(INDIRECT(ADDRESS(16,6, 1,TRUE,$A49)),0) -> 36 | G49: =IFERROR(INDIRECT(ADDRESS(16,7, 1,TRUE,$A49)),0) -> 28 | H49: =F49-G49 -> 8 | I49: =E49-F49 -> 0 | J49: =IFERROR(INDIRECT(ADDRESS(16,8, 1,TRUE,$A49)),0) -> 107 | K49: =IFERROR(INDIRECT(ADDRESS(16,9, 1,TRUE,$A49)),0) -> 84 | L49: =IFERROR(INDIRECT(ADDRESS(16,10, 1,TRUE,$A49)),0) -> 0.78504673
A50: =IFERROR(자산목록!$A14,"-") -> U_010 | C50: =IFERROR(VLOOKUP($A50,자산목록!$A$1:$H$854,2,FALSE),"-") -> pcespg-api-admin-74df64559f-5wgfk | E50: =IFERROR(INDIRECT(ADDRESS(16, 5, 1,TRUE,$A50)),0) -> 36 | F50: =IFERROR(INDIRECT(ADDRESS(16,6, 1,TRUE,$A50)),0) -> 36 | G50: =IFERROR(INDIRECT(ADDRESS(16,7, 1,TRUE,$A50)),0) -> 28 | H50: =F50-G50 -> 8 | I50: =E50-F50 -> 0 | J50: =IFERROR(INDIRECT(ADDRESS(16,8, 1,TRUE,$A50)),0) -> 107 | K50: =IFERROR(INDIRECT(ADDRESS(16,9, 1,TRUE,$A50)),0) -> 84 | L50: =IFERROR(INDIRECT(ADDRESS(16,10, 1,TRUE,$A50)),0) -> 0.78504673
A51: =IFERROR(자산목록!$A15,"-") -> U_011 | C51: =IFERROR(VLOOKUP($A51,자산목록!$A$1:$H$854,2,FALSE),"-") -> pcespg-api-admin-74df64559f-rrwrl | E51: =IFERROR(INDIRECT(ADDRESS(16, 5, 1,TRUE,$A51)),0) -> 36 | F51: =IFERROR(INDIRECT(ADDRESS(16,6, 1,TRUE,$A51)),0) -> 36 | G51: =IFERROR(INDIRECT(ADDRESS(16,7, 1,TRUE,$A51)),0) -> 28 | H51: =F51-G51 -> 8 | I51: =E51-F51 -> 0 | J51: =IFERROR(INDIRECT(ADDRESS(16,8, 1,TRUE,$A51)),0) -> 107 | K51: =IFERROR(INDIRECT(ADDRESS(16,9, 1,TRUE,$A51)),0) -> 84 | L51: =IFERROR(INDIRECT(ADDRESS(16,10, 1,TRUE,$A51)),0) -> 0.78504673
A52: =IFERROR(자산목록!$A16,"-") -> U_012 | C52: =IFERROR(VLOOKUP($A52,자산목록!$A$1:$H$854,2,FALSE),"-") -> pcespg-api-biz-5749fc55dc-sj9mp | E52: =IFERROR(INDIRECT(ADDRESS(16, 5, 1,TRUE,$A52)),0) -> 36 | F52: =IFERROR(INDIRECT(ADDRESS(16,6, 1,TRUE,$A52)),0) -> 36 | G52: =IFERROR(INDIRECT(ADDRESS(16,7, 1,TRUE,$A52)),0) -> 28 | H52: =F52-G52 -> 8 | I52: =E52-F52 -> 0 | J52: =IFERROR(INDIRECT(ADDRESS(16,8, 1,TRUE,$A52)),0) -> 107 | K52: =IFERROR(INDIRECT(ADDRESS(16,9, 1,TRUE,$A52)),0) -> 84 | L52: =IFERROR(INDIRECT(ADDRESS(16,10, 1,TRUE,$A52)),0) -> 0.78504673
... A58: =IFERROR(자산목록!$A22,"-") -> U_018 | C58: =IFERROR(VLOOKUP($A58,자산목록!$A$1:$H$854,2,FALSE),"-") -> gaia | E58: =IFERROR(INDIRECT(ADDRESS(16, 5, 1,TRUE,$A58)),0) -> 36 | F58: =IFERROR(INDIRECT(ADDRESS(16,6, 1,TRUE,$A58)),0) -> 36 | G58: =IFERROR(INDIRECT(ADDRESS(16,7, 1,TRUE,$A58)),0) -> 28 | H58: =F58-G58 -> 8 | I58: =E58-F58 -> 0 | J58: =IFERROR(INDIRECT(ADDRESS(16,8, 1,TRUE,$A58)),0) -> 107 | K58: =IFERROR(INDIRECT(ADDRESS(16,9, 1,TRUE,$A58)),0) -> 84 | L58: =IFERROR(INDIRECT(ADDRESS(16,10, 1,TRUE,$A58)),0) -> 0.78504673
A59: 계 | E59: =SUM(E41:E58) -> 648 | F59: =SUM(F41:F58) -> 648 | G59: =SUM(G41:G58) -> 520 | H59: =SUM(H41:H58) -> 128 | I59: =SUM(I41:I58) -> 0 | J59: =SUM(J41:J58) -> 1926 | K59: =SUM(K41:K58) -> 1557 | L59: =IFERROR(K59/J59, 0) -> 0.80841121

Sheet 항목별 통계
A1: 항목별 통계
A3: =ChkList!A4 -> 분류 | D3: =ChkList!C4 -> 점검항목 | E3: =ChkList!D4 -> 중요도 | F3: 점검 통계 | J3: 중요도 점수 | L3: 점검결과 | M3: 점검결과 | N3: 점검결과 | O3: 점검결과 | P3: 점검결과 | Q3: 점검결과 | R3: 점검결과 | S3: 점검결과 | T3: 점검결과 | U3: 점검결과 | V3: 점검결과 | W3: 점검결과 | X3: 점검결과 | Y3: 점검결과 | Z3: 점검결과 | AA3: 점검결과 | AB3: 점검결과 | AC3: 점검결과
F4: 전체 | G4: 양호 | H4: 취약 | I4: 해당없음 | J4: 전체 | K4: 평가 | L4: =HYPERLINK("[" & MID(CELL("filename"),SEARCH("[",CELL("filename"))+1, SEARCH("]",CELL("filename"))-SEARCH("[",CELL("filename"))-1) & "]" & INDIRECT(ADDRESS(COLUMN()-7,1,1,TRUE,"자산목록")) & "!A1",INDIRECT(ADDRESS(COLUMN()-7,1,1,TRUE,"자산목록"))) -> U_001 | M4: =HYPERLINK("[" & MID(CELL("filename"),SEARCH("[",CELL("filename"))+1, SEARCH("]",CELL("filename"))-SEARCH("[",CELL("filename"))-1) & "]" & INDIRECT(ADDRESS(COLUMN()-7,1,1,TRUE,"자산목록")) & "!A1",INDIRECT(ADDRESS(COLUMN()-7,1,1,TRUE,"자산목록"))) -> U_002 | N4: =HYPERLINK("[" & MID(CELL("filename"),SEARCH("[",CELL("filename"))+1, SEARCH("]",CELL("filename"))-SEARCH("[",CELL("filename"))-1) & "]" & INDIRECT(ADDRESS(COLUMN()-7,1,1,TRUE,"자산목록")) & "!A1",INDIRECT(ADDRESS(COLUMN()-7,1,1,TRUE,"자산목록"))) -> U_003 | O4: =HYPERLINK("[" & MID(CELL("filename"),SEARCH("[",CELL("filename"))+1, SEARCH("]",CELL("filename"))-SEARCH("[",CELL("filename"))-1) & "]" & INDIRECT(ADDRESS(COLUMN()-7,1,1,TRUE,"자산목록")) & "!A1",INDIRECT(ADDRESS(COLUMN()-7,1,1,TRUE,"자산목록"))) -> U_004 | P4: =HYPERLINK("[" & MID(CELL("filename"),SEARCH("[",CELL("filename"))+1, SEARCH("]",CELL("filename"))-SEARCH("[",CELL("filename"))-1) & "]" & INDIRECT(ADDRESS(COLUMN()-7,1,1,TRUE,"자산목록")) & "!A1",INDIRECT(ADDRESS(COLUMN()-7,1,1,TRUE,"자산목록"))) -> U_005 | Q4: =HYPERLINK("[" & MID(CELL("filename"),SEARCH("[",CELL("filename"))+1, SEARCH("]",CELL("filename"))-SEARCH("[",CELL("filename"))-1) & "]" & INDIRECT(ADDRESS(COLUMN()-7,1,1,TRUE,"자산목록")) & "!A1",INDIRECT(ADDRESS(COLUMN()-7,1,1,TRUE,"자산목록"))) -> U_006 | R4: =HYPERLINK("[" & MID(CELL("filename"),SEARCH("[",CELL("filename"))+1, SEARCH("]",CELL("filename"))-SEARCH("[",CELL("filename"))-1) & "]" & INDIRECT(ADDRESS(COLUMN()-7,1,1,TRUE,"자산목록")) & "!A1",INDIRECT(ADDRESS(COLUMN()-7,1,1,TRUE,"자산목록"))) -> U_007 | S4: =HYPERLINK("[" & MID(CELL("filename"),SEARCH("[",CELL("filename"))+1, SEARCH("]",CELL("filename"))-SEARCH("[",CELL("filename"))-1) & "]" & INDIRECT(ADDRESS(COLUMN()-7,1,1,TRUE,"자산목록")) & "!A1",INDIRECT(ADDRESS(COLUMN()-7,1,1,TRUE,"자산목록"))) -> U_008 | ... AC4: =HYPERLINK("[" & MID(CELL("filename"),SEARCH("[",CELL("filename"))+1, SEARCH("]",CELL("filename"))-SEARCH("[",CELL("filename"))-1) & "]" & INDIRECT(ADDRESS(COLUMN()-7,1,1,TRUE,"자산목록")) & "!A1",INDIRECT(ADDRESS(COLUMN()-7,1,1,TRUE,"자산목록"))) -> U_018
A5: =ChkList!$A$5 -> U1 | C5: =VLOOKUP($A5,ChkList!$A$5:$B$44,2,FALSE) -> 계정 관리
B6: U1-01 | C6: =ChkList!$B6 -> U-01 | D6: =ChkList!$C6 -> root 계정 원격 접속 제한 | E6: =ChkList!$D6 -> H | F6: =COUNTA($L6:INDIRECT(ADDRESS(ROW(),MATCH("",$4:$4,-1),1,1))) -> 18 | G6: =COUNTIF($L6:INDIRECT(ADDRESS(ROW(),MATCH("",$4:$4,-1),1,1)),"Y") -> 5 | H6: =COUNTIF($L6:INDIRECT(ADDRESS(ROW(),MATCH("",$4:$4,-1),1,1)),"N") -> 13 | I6: =COUNTIF($L6:INDIRECT(ADDRESS(ROW(),MATCH("",$4:$4,-1),1,1)),"N/A") -> 0 | J6: =VLOOKUP($E6,ChkList!$A$47:$B$49,2,FALSE)*($F6-$I6) -> 54 | K6: =VLOOKUP($E6,ChkList!$A$47:$B$49,2,FALSE)*$G6 -> 15 | L6: =IFERROR(INDIRECT(ADDRESS(ROW()+15,10,1,TRUE,L$4)),"") -> Y | M6: =IFERROR(INDIRECT(ADDRESS(ROW()+15,10,1,TRUE,M$4)),"") -> Y | N6: =IFERROR(INDIRECT(ADDRESS(ROW()+15,10,1,TRUE,N$4)),"") -> Y | O6: =IFERROR(INDIRECT(ADDRESS(ROW()+15,10,1,TRUE,O$4)),"") -> Y | P6: =IFERROR(INDIRECT(ADDRESS(ROW()+15,10,1,TRUE,P$4)),"") -> Y | Q6: =IFERROR(INDIRECT(ADDRESS(ROW()+15,10,1,TRUE,Q$4)),"") -> N | R6: =IFERROR(INDIRECT(ADDRESS(ROW()+15,10,1,TRUE,R$4)),"") -> N | S6: =IFERROR(INDIRECT(ADDRESS(ROW()+15,10,1,TRUE,S$4)),"") -> N | ... AC6: =IFERROR(INDIRECT(ADDRESS(ROW()+15,10,1,TRUE,AC$4)),"") -> N
B7: U1-02 | C7: =ChkList!$B7 -> U-02 | D7: =ChkList!$C7 -> 패스워드 복잡성 설정 | E7: =ChkList!$D7 -> H | F7: =COUNTA($L7:INDIRECT(ADDRESS(ROW(),MATCH("",$4:$4,-1),1,1))) -> 18 | G7: =COUNTIF($L7:INDIRECT(ADDRESS(ROW(),MATCH("",$4:$4,-1),1,1)),"Y") -> 1 | H7: =COUNTIF($L7:INDIRECT(ADDRESS(ROW(),MATCH("",$4:$4,-1),1,1)),"N") -> 17 | I7: =COUNTIF($L7:INDIRECT(ADDRESS(ROW(),MATCH("",$4:$4,-1),1,1)),"N/A") -> 0 | J7: =VLOOKUP($E7,ChkList!$A$47:$B$49,2,FALSE)*($F7-$I7) -> 54 | K7: =VLOOKUP($E7,ChkList!$A$47:$B$49,2,FALSE)*$G7 -> 3 | L7: =IFERROR(INDIRECT(ADDRESS(ROW()+15,10,1,TRUE,L$4)),"") -> N | M7: =IFERROR(INDIRECT(ADDRESS(ROW()+15,10,1,TRUE,M$4)),"") -> N | N7: =IFERROR(INDIRECT(ADDRESS(ROW()+15,10,1,TRUE,N$4)),"") -> Y | O7: =IFERROR(INDIRECT(ADDRESS(ROW()+15,10,1,TRUE,O$4)),"") -> N | P7: =IFERROR(INDIRECT(ADDRESS(ROW()+15,10,1,TRUE,P$4)),"") -> N | Q7: =IFERROR(INDIRECT(ADDRESS(ROW()+15,10,1,TRUE,Q$4)),"") -> N | R7: =IFERROR(INDIRECT(ADDRESS(ROW()+15,10,1,TRUE,R$4)),"") -> N | S7: =IFERROR(INDIRECT(ADDRESS(ROW()+15,10,1,TRUE,S$4)),"") -> N | ... AC7: =IFERROR(INDIRECT(ADDRESS(ROW()+15,10,1,TRUE,AC$4)),"") -> N
B8: U1-03 | C8: =ChkList!$B8 -> U-03 | D8: =ChkList!$C8 -> 계정 잠금 임계값 설정 | E8: =ChkList!$D8 -> H | F8: =COUNTA($L8:INDIRECT(ADDRESS(ROW(),MATCH("",$4:$4,-1),1,1))) -> 18 | G8: =COUNTIF($L8:INDIRECT(ADDRESS(ROW(),MATCH("",$4:$4,-1),1,1)),"Y") -> 5 | H8: =COUNTIF($L8:INDIRECT(ADDRESS(ROW(),MATCH("",$4:$4,-1),1,1)),"N") -> 13 | I8: =COUNTIF($L8:INDIRECT(ADDRESS(ROW(),MATCH("",$4:$4,-1),1,1)),"N/A") -> 0 | J8: =VLOOKUP($E8,ChkList!$A$47:$B$49,2,FALSE)*($F8-$I8) -> 54 | K8: =VLOOKUP($E8,ChkList!$A$47:$B$49,2,FALSE)*$G8 -> 15 | L8: =IFERROR(INDIRECT(ADDRESS(ROW()+15,10,1,TRUE,L$4)),"") -> Y | M8: =IFERROR(INDIRECT(ADDRESS(ROW()+15,10,1,TRUE,M$4)),"") -> Y | N8: =IFERROR(INDIRECT(ADDRESS(ROW()+15,10,1,TRUE,N$4)),"") -> Y | O8: =IFERROR(INDIRECT(ADDRESS(ROW()+15,10,1,TRUE,O$4)),"") -> Y | P8: =IFERROR(INDIRECT(ADDRESS(ROW()+15,10,1,TRUE,P$4)),"") -> Y | Q8: =IFERROR(INDIRECT(ADDRESS(ROW()+15,10,1,TRUE,Q$4)),"") -> N | R8: =IFERROR(INDIRECT(ADDRESS(ROW()+15,10,1,TRUE,R$4)),"") -> N | S8: =IFERROR(INDIRECT(ADDRESS(ROW()+15,10,1,TRUE,S$4)),"") -> N | ... AC8: =IFERROR(INDIRECT(ADDRESS(ROW()+15,10,1,TRUE,AC$4)),"") -> N
B9: U1-04 | C9: =ChkList!$B9 -> U-04 | D9: =ChkList!$C9 -> 패스워드 최대 사용 기간 설정 | E9: =ChkList!$D9 -> M | F9: =COUNTA($L9:INDIRECT(ADDRESS(ROW(),MATCH("",$4:$4,-1),1,1))) -> 18 | G9: =COUNTIF($L9:INDIRECT(ADDRESS(ROW(),MATCH("",$4:$4,-1),1,1)),"Y") -> 3 | H9: =COUNTIF($L9:INDIRECT(ADDRESS(ROW(),MATCH("",$4:$4,-1),1,1)),"N") -> 15 | I9: =COUNTIF($L9:INDIRECT(ADDRESS(ROW(),MATCH("",$4:$4,-1),1,1)),"N/A") -> 0 | J9: =VLOOKUP($E9,ChkList!$A$47:$B$49,2,FALSE)*($F9-$I9) -> 36 | K9: =VLOOKUP($E9,ChkList!$A$47:$B$49,2,FALSE)*$G9 -> 6 | L9: =IFERROR(INDIRECT(ADDRESS(ROW()+15,10,1,TRUE,L$4)),"") -> Y | M9: =IFERROR(INDIRECT(ADDRESS(ROW()+15,10,1,TRUE,M$4)),"") -> Y | N9: =IFERROR(INDIRECT(ADDRESS(ROW()+15,10,1,TRUE,N$4)),"") -> Y | O9: =IFERROR(INDIRECT(ADDRESS(ROW()+15,10,1,TRUE,O$4)),"") -> N | P9: =IFERROR(INDIRECT(ADDRESS(ROW()+15,10,1,TRUE,P$4)),"") -> N | Q9: =IFERROR(INDIRECT(ADDRESS(ROW()+15,10,1,TRUE,Q$4)),"") -> N | R9: =IFERROR(INDIRECT(ADDRESS(ROW()+15,10,1,TRUE,R$4)),"") -> N | S9: =IFERROR(INDIRECT(ADDRESS(ROW()+15,10,1,TRUE,S$4)),"") -> N | ... AC9: =IFERROR(INDIRECT(ADDRESS(ROW()+15,10,1,TRUE,AC$4)),"") -> N
B10: U1-05 | C10: =ChkList!$B10 -> U-05 | D10: =ChkList!$C10 -> 패스워드 파일 보호 | E10: =ChkList!$D10 -> H | F10: =COUNTA($L10:INDIRECT(ADDRESS(ROW(),MATCH("",$4:$4,-1),1,1))) -> 18 | G10: =COUNTIF($L10:INDIRECT(ADDRESS(ROW(),MATCH("",$4:$4,-1),1,1)),"Y") -> 18 | H10: =COUNTIF($L10:INDIRECT(ADDRESS(ROW(),MATCH("",$4:$4,-1),1,1)),"N") -> 0 | I10: =COUNTIF($L10:INDIRECT(ADDRESS(ROW(),MATCH("",$4:$4,-1),1,1)),"N/A") -> 0 | J10: =VLOOKUP($E10,ChkList!$A$47:$B$49,2,FALSE)*($F10-$I10) -> 54 | K10: =VLOOKUP($E10,ChkList!$A$47:$B$49,2,FALSE)*$G10 -> 54 | L10: =IFERROR(INDIRECT(ADDRESS(ROW()+15,10,1,TRUE,L$4)),"") -> Y | M10: =IFERROR(INDIRECT(ADDRESS(ROW()+15,10,1,TRUE,M$4)),"") -> Y | N10: =IFERROR(INDIRECT(ADDRESS(ROW()+15,10,1,TRUE,N$4)),"") -> Y | O10: =IFERROR(INDIRECT(ADDRESS(ROW()+15,10,1,TRUE,O$4)),"") -> Y | P10: =IFERROR(INDIRECT(ADDRESS(ROW()+15,10,1,TRUE,P$4)),"") -> Y | Q10: =IFERROR(INDIRECT(ADDRESS(ROW()+15,10,1,TRUE,Q$4)),"") -> Y | R10: =IFERROR(INDIRECT(ADDRESS(ROW()+15,10,1,TRUE,R$4)),"") -> Y | S10: =IFERROR(INDIRECT(ADDRESS(ROW()+15,10,1,TRUE,S$4)),"") -> Y | ... AC10: =IFERROR(INDIRECT(ADDRESS(ROW()+15,10,1,TRUE,AC$4)),"") -> Y
A11: =ChkList!$A$11 -> U2 | C11: =VLOOKUP($A11,ChkList!$A$5:$B$44,2,FALSE) -> 파일 및 디렉토리 관리
B12: U2-01 | C12: =ChkList!$B12 -> U-06 | D12: =ChkList!$C12 -> root 홈, 패스 디렉터리 권한 및 패스 설정 | E12: =ChkList!$D12 -> H | F12: =COUNTA($L12:INDIRECT(ADDRESS(ROW(),MATCH("",$4:$4,-1),1,1))) -> 18 | G12: =COUNTIF($L12:INDIRECT(ADDRESS(ROW(),MATCH("",$4:$4,-1),1,1)),"Y") -> 18 | H12: =COUNTIF($L12:INDIRECT(ADDRESS(ROW(),MATCH("",$4:$4,-1),1,1)),"N") -> 0 | I12: =COUNTIF($L12:INDIRECT(ADDRESS(ROW(),MATCH("",$4:$4,-1),1,1)),"N/A") -> 0 | J12: =VLOOKUP($E12,ChkList!$A$47:$B$49,2,FALSE)*($F12-$I12) -> 54 | K12: =VLOOKUP($E12,ChkList!$A$47:$B$49,2,FALSE)*$G12 -> 54 | L12: =IFERROR(INDIRECT(ADDRESS(ROW()+15,10,1,TRUE,L$4)),"") -> Y | M12: =IFERROR(INDIRECT(ADDRESS(ROW()+15,10,1,TRUE,M$4)),"") -> Y | N12: =IFERROR(INDIRECT(ADDRESS(ROW()+15,10,1,TRUE,N$4)),"") -> Y | O12: =IFERROR(INDIRECT(ADDRESS(ROW()+15,10,1,TRUE,O$4)),"") -> Y | P12: =IFERROR(INDIRECT(ADDRESS(ROW()+15,10,1,TRUE,P$4)),"") -> Y | Q12: =IFERROR(INDIRECT(ADDRESS(ROW()+15,10,1,TRUE,Q$4)),"") -> Y | R12: =IFERROR(INDIRECT(ADDRESS(ROW()+15,10,1,TRUE,R$4)),"") -> Y | S12: =IFERROR(INDIRECT(ADDRESS(ROW()+15,10,1,TRUE,S$4)),"") -> Y | ... AC12: =IFERROR(INDIRECT(ADDRESS(ROW()+15,10,1,TRUE,AC$4)),"") -> Y
B13: U2-02 | C13: =ChkList!$B13 -> U-07 | D13: =ChkList!$C13 -> 파일 및 디렉터리 소유자 설정 | E13: =ChkList!$D13 -> H | F13: =COUNTA($L13:INDIRECT(ADDRESS(ROW(),MATCH("",$4:$4,-1),1,1))) -> 18 | G13: =COUNTIF($L13:INDIRECT(ADDRESS(ROW(),MATCH("",$4:$4,-1),1,1)),"Y") -> 18 | H13: =COUNTIF($L13:INDIRECT(ADDRESS(ROW(),MATCH("",$4:$4,-1),1,1)),"N") -> 0 | I13: =COUNTIF($L13:INDIRECT(ADDRESS(ROW(),MATCH("",$4:$4,-1),1,1)),"N/A") -> 0 | J13: =VLOOKUP($E13,ChkList!$A$47:$B$49,2,FALSE)*($F13-$I13) -> 54 | K13: =VLOOKUP($E13,ChkList!$A$47:$B$49,2,FALSE)*$G13 -> 54 | L13: =IFERROR(INDIRECT(ADDRESS(ROW()+15,10,1,TRUE,L$4)),"") -> Y | M13: =IFERROR(INDIRECT(ADDRESS(ROW()+15,10,1,TRUE,M$4)),"") -> Y | N13: =IFERROR(INDIRECT(ADDRESS(ROW()+15,10,1,TRUE,N$4)),"") -> Y | O13: =IFERROR(INDIRECT(ADDRESS(ROW()+15,10,1,TRUE,O$4)),"") -> Y | P13: =IFERROR(INDIRECT(ADDRESS(ROW()+15,10,1,TRUE,P$4)),"") -> Y | Q13: =IFERROR(INDIRECT(ADDRESS(ROW()+15,10,1,TRUE,Q$4)),"") -> Y | R13: =IFERROR(INDIRECT(ADDRESS(ROW()+15,10,1,TRUE,R$4)),"") -> Y | S13: =IFERROR(INDIRECT(ADDRESS(ROW()+15,10,1,TRUE,S$4)),"") -> Y | ... AC13: =IFERROR(INDIRECT(ADDRESS(ROW()+15,10,1,TRUE,AC$4)),"") -> Y
B14: U2-03 | C14: =ChkList!$B14 -> U-08 | D14: =ChkList!$C14 -> /etc/passwd 파일 소유자 및 권한 설정 | E14: =ChkList!$D14 -> H | F14: =COUNTA($L14:INDIRECT(ADDRESS(ROW(),MATCH("",$4:$4,-1),1,1))) -> 18 | G14: =COUNTIF($L14:INDIRECT(ADDRESS(ROW(),MATCH("",$4:$4,-1),1,1)),"Y") -> 18 | H14: =COUNTIF($L14:INDIRECT(ADDRESS(ROW(),MATCH("",$4:$4,-1),1,1)),"N") -> 0 | I14: =COUNTIF($L14:INDIRECT(ADDRESS(ROW(),MATCH("",$4:$4,-1),1,1)),"N/A") -> 0 | J14: =VLOOKUP($E14,ChkList!$A$47:$B$49,2,FALSE)*($F14-$I14) -> 54 | K14: =VLOOKUP($E14,ChkList!$A$47:$B$49,2,FALSE)*$G14 -> 54 | L14: =IFERROR(INDIRECT(ADDRESS(ROW()+15,10,1,TRUE,L$4)),"") -> Y | M14: =IFERROR(INDIRECT(ADDRESS(ROW()+15,10,1,TRUE,M$4)),"") -> Y | N14: =IFERROR(INDIRECT(ADDRESS(ROW()+15,10,1,TRUE,N$4)),"") -> Y | O14: =IFERROR(INDIRECT(ADDRESS(ROW()+15,10,1,TRUE,O$4)),"") -> Y | P14: =IFERROR(INDIRECT(ADDRESS(ROW()+15,10,1,TRUE,P$4)),"") -> Y | Q14: =IFERROR(INDIRECT(ADDRESS(ROW()+15,10,1,TRUE,Q$4)),"") -> Y | R14: =IFERROR(INDIRECT(ADDRESS(ROW()+15,10,1,TRUE,R$4)),"") -> Y | S14: =IFERROR(INDIRECT(ADDRESS(ROW()+15,10,1,TRUE,S$4)),"") -> Y | ... AC14: =IFERROR(INDIRECT(ADDRESS(ROW()+15,10,1,TRUE,AC$4)),"") -> Y
B15: U2-04 | C15: =ChkList!$B15 -> U-09 | D15: =ChkList!$C15 -> /etc/shadow 파일 소유자 및 권한 설정 | E15: =ChkList!$D15 -> H | F15: =COUNTA($L15:INDIRECT(ADDRESS(ROW(),MATCH("",$4:$4,-1),1,1))) -> 18 | G15: =COUNTIF($L15:INDIRECT(ADDRESS(ROW(),MATCH("",$4:$4,-1),1,1)),"Y") -> 18 | H15: =COUNTIF($L15:INDIRECT(ADDRESS(ROW(),MATCH("",$4:$4,-1),1,1)),"N") -> 0 | I15: =COUNTIF($L15:INDIRECT(ADDRESS(ROW(),MATCH("",$4:$4,-1),1,1)),"N/A") -> 0 | J15: =VLOOKUP($E15,ChkList!$A$47:$B$49,2,FALSE)*($F15-$I15) -> 54 | K15: =VLOOKUP($E15,ChkList!$A$47:$B$49,2,FALSE)*$G15 -> 54 | L15: =IFERROR(INDIRECT(ADDRESS(ROW()+15,10,1,TRUE,L$4)),"") -> Y | M15: =IFERROR(INDIRECT(ADDRESS(ROW()+15,10,1,TRUE,M$4)),"") -> Y | N15: =IFERROR(INDIRECT(ADDRESS(ROW()+15,10,1,TRUE,N$4)),"") -> Y | O15: =IFERROR(INDIRECT(ADDRESS(ROW()+15,10,1,TRUE,O$4)),"") -> Y | P15: =IFERROR(INDIRECT(ADDRESS(ROW()+15,10,1,TRUE,P$4)),"") -> Y | Q15: =IFERROR(INDIRECT(ADDRESS(ROW()+15,10,1,TRUE,Q$4)),"") -> Y | R15: =IFERROR(INDIRECT(ADDRESS(ROW()+15,10,1,TRUE,R$4)),"") -> Y | S15: =IFERROR(INDIRECT(ADDRESS(ROW()+15,10,1,TRUE,S$4)),"") -> Y | ... AC15: =IFERROR(INDIRECT(ADDRESS(ROW()+15,10,1,TRUE,AC$4)),"") -> Y
B16: U2-05 | C16: =ChkList!$B16 -> U-10 | D16: =ChkList!$C16 -> /etc/hosts 파일 소유자 및 권한 설정 | E16: =ChkList!$D16 -> H | F16: =COUNTA($L16:INDIRECT(ADDRESS(ROW(),MATCH("",$4:$4,-1),1,1))) -> 18 | G16: =COUNTIF($L16:INDIRECT(ADDRESS(ROW(),MATCH("",$4:$4,-1),1,1)),"Y") -> 18 | H16: =COUNTIF($L16:INDIRECT(ADDRESS(ROW(),MATCH("",$4:$4,-1),1,1)),"N") -> 0 | I16: =COUNTIF($L16:INDIRECT(ADDRESS(ROW(),MATCH("",$4:$4,-1),1,1)),"N/A") -> 0 | J16: =VLOOKUP($E16,ChkList!$A$47:$B$49,2,FALSE)*($F16-$I16) -> 54 | K16: =VLOOKUP($E16,ChkList!$A$47:$B$49,2,FALSE)*$G16 -> 54 | L16: =IFERROR(INDIRECT(ADDRESS(ROW()+15,10,1,TRUE,L$4)),"") -> Y | M16: =IFERROR(INDIRECT(ADDRESS(ROW()+15,10,1,TRUE,M$4)),"") -> Y | N16: =IFERROR(INDIRECT(ADDRESS(ROW()+15,10,1,TRUE,N$4)),"") -> Y | O16: =IFERROR(INDIRECT(ADDRESS(ROW()+15,10,1,TRUE,O$4)),"") -> Y | P16: =IFERROR(INDIRECT(ADDRESS(ROW()+15,10,1,TRUE,P$4)),"") -> Y | Q16: =IFERROR(INDIRECT(ADDRESS(ROW()+15,10,1,TRUE,Q$4)),"") -> Y | R16: =IFERROR(INDIRECT(ADDRESS(ROW()+15,10,1,TRUE,R$4)),"") -> Y | S16: =IFERROR(INDIRECT(ADDRESS(ROW()+15,10,1,TRUE,S$4)),"") -> Y | ... AC16: =IFERROR(INDIRECT(ADDRESS(ROW()+15,10,1,TRUE,AC$4)),"") -> Y
B17: U2-06 | C17: =ChkList!$B17 -> U-11 | D17: =ChkList!$C17 -> /etc/(x)inetd.conf 파일 소유자 및 권한 설정 | E17: =ChkList!$D17 -> H | F17: =COUNTA($L17:INDIRECT(ADDRESS(ROW(),MATCH("",$4:$4,-1),1,1))) -> 18 | G17: =COUNTIF($L17:INDIRECT(ADDRESS(ROW(),MATCH("",$4:$4,-1),1,1)),"Y") -> 18 | H17: =COUNTIF($L17:INDIRECT(ADDRESS(ROW(),MATCH("",$4:$4,-1),1,1)),"N") -> 0 | I17: =COUNTIF($L17:INDIRECT(ADDRESS(ROW(),MATCH("",$4:$4,-1),1,1)),"N/A") -> 0 | J17: =VLOOKUP($E17,ChkList!$A$47:$B$49,2,FALSE)*($F17-$I17) -> 54 | K17: =VLOOKUP($E17,ChkList!$A$47:$B$49,2,FALSE)*$G17 -> 54 | L17: =IFERROR(INDIRECT(ADDRESS(ROW()+15,10,1,TRUE,L$4)),"") -> Y | M17: =IFERROR(INDIRECT(ADDRESS(ROW()+15,10,1,TRUE,M$4)),"") -> Y | N17: =IFERROR(INDIRECT(ADDRESS(ROW()+15,10,1,TRUE,N$4)),"") -> Y | O17: =IFERROR(INDIRECT(ADDRESS(ROW()+15,10,1,TRUE,O$4)),"") -> Y | P17: =IFERROR(INDIRECT(ADDRESS(ROW()+15,10,1,TRUE,P$4)),"") -> Y | Q17: =IFERROR(INDIRECT(ADDRESS(ROW()+15,10,1,TRUE,Q$4)),"") -> Y | R17: =IFERROR(INDIRECT(ADDRESS(ROW()+15,10,1,TRUE,R$4)),"") -> Y | S17: =IFERROR(INDIRECT(ADDRESS(ROW()+15,10,1,TRUE,S$4)),"") -> Y | ... AC17: =IFERROR(INDIRECT(ADDRESS(ROW()+15,10,1,TRUE,AC$4)),"") -> Y
B18: U2-07 | C18: =ChkList!$B18 -> U-12 | D18: =ChkList!$C18 -> /etc/syslog.conf 파일 소유자 및 권한 설정 | E18: =ChkList!$D18 -> H | F18: =COUNTA($L18:INDIRECT(ADDRESS(ROW(),MATCH("",$4:$4,-1),1,1))) -> 18 | G18: =COUNTIF($L18:INDIRECT(ADDRESS(ROW(),MATCH("",$4:$4,-1),1,1)),"Y") -> 18 | H18: =COUNTIF($L18:INDIRECT(ADDRESS(ROW(),MATCH("",$4:$4,-1),1,1)),"N") -> 0 | I18: =COUNTIF($L18:INDIRECT(ADDRESS(ROW(),MATCH("",$4:$4,-1),1,1)),"N/A") -> 0 | J18: =VLOOKUP($E18,ChkList!$A$47:$B$49,2,FALSE)*($F18-$I18) -> 54 | K18: =VLOOKUP($E18,ChkList!$A$47:$B$49,2,FALSE)*$G18 -> 54 | L18: =IFERROR(INDIRECT(ADDRESS(ROW()+15,10,1,TRUE,L$4)),"") -> Y | M18: =IFERROR(INDIRECT(ADDRESS(ROW()+15,10,1,TRUE,M$4)),"") -> Y | N18: =IFERROR(INDIRECT(ADDRESS(ROW()+15,10,1,TRUE,N$4)),"") -> Y | O18: =IFERROR(INDIRECT(ADDRESS(ROW()+15,10,1,TRUE,O$4)),"") -> Y | P18: =IFERROR(INDIRECT(ADDRESS(ROW()+15,10,1,TRUE,P$4)),"") -> Y | Q18: =IFERROR(INDIRECT(ADDRESS(ROW()+15,10,1,TRUE,Q$4)),"") -> Y | R18: =IFERROR(INDIRECT(ADDRESS(ROW()+15,10,1,TRUE,R$4)),"") -> Y | S18: =IFERROR(INDIRECT(ADDRESS(ROW()+15,10,1,TRUE,S$4)),"") -> Y | ... AC18: =IFERROR(INDIRECT(ADDRESS(ROW()+15,10,1,TRUE,AC$4)),"") -> Y
B19: U2-08 | C19: =ChkList!$B19 -> U-13 | D19: =ChkList!$C19 -> /etc/services 파일 소유자 및 권한 설정 | E19: =ChkList!$D19 -> H | F19: =COUNTA($L19:INDIRECT(ADDRESS(ROW(),MATCH("",$4:$4,-1),1,1))) -> 18 | G19: =COUNTIF($L19:INDIRECT(ADDRESS(ROW(),MATCH("",$4:$4,-1),1,1)),"Y") -> 18 | H19: =COUNTIF($L19:INDIRECT(ADDRESS(ROW(),MATCH("",$4:$4,-1),1,1)),"N") -> 0 | I19: =COUNTIF($L19:INDIRECT(ADDRESS(ROW(),MATCH("",$4:$4,-1),1,1)),"N/A") -> 0 | J19: =VLOOKUP($E19,ChkList!$A$47:$B$49,2,FALSE)*($F19-$I19) -> 54 | K19: =VLOOKUP($E19,ChkList!$A$47:$B$49,2,FALSE)*$G19 -> 54 | L19: =IFERROR(INDIRECT(ADDRESS(ROW()+15,10,1,TRUE,L$4)),"") -> Y | M19: =IFERROR(INDIRECT(ADDRESS(ROW()+15,10,1,TRUE,M$4)),"") -> Y | N19: =IFERROR(INDIRECT(ADDRESS(ROW()+15,10,1,TRUE,N$4)),"") -> Y | O19: =IFERROR(INDIRECT(ADDRESS(ROW()+15,10,1,TRUE,O$4)),"") -> Y | P19: =IFERROR(INDIRECT(ADDRESS(ROW()+15,10,1,TRUE,P$4)),"") -> Y | Q19: =IFERROR(INDIRECT(ADDRESS(ROW()+15,10,1,TRUE,Q$4)),"") -> Y | R19: =IFERROR(INDIRECT(ADDRESS(ROW()+15,10,1,TRUE,R$4)),"") -> Y | S19: =IFERROR(INDIRECT(ADDRESS(ROW()+15,10,1,TRUE,S$4)),"") -> Y | ... AC19: =IFERROR(INDIRECT(ADDRESS(ROW()+15,10,1,TRUE,AC$4)),"") -> Y
B20: U2-09 | C20: =ChkList!$B20 -> U-14 | D20: =ChkList!$C20 -> SUID, SGID, Sticky bit 설정 파일 점검 | E20: =ChkList!$D20 -> H | F20: =COUNTA($L20:INDIRECT(ADDRESS(ROW(),MATCH("",$4:$4,-1),1,1))) -> 18 | G20: =COUNTIF($L20:INDIRECT(ADDRESS(ROW(),MATCH("",$4:$4,-1),1,1)),"Y") -> 5 | H20: =COUNTIF($L20:INDIRECT(ADDRESS(ROW(),MATCH("",$4:$4,-1),1,1)),"N") -> 13 | I20: =COUNTIF($L20:INDIRECT(ADDRESS(ROW(),MATCH("",$4:$4,-1),1,1)),"N/A") -> 0 | J20: =VLOOKUP($E20,ChkList!$A$47:$B$49,2,FALSE)*($F20-$I20) -> 54 | K20: =VLOOKUP($E20,ChkList!$A$47:$B$49,2,FALSE)*$G20 -> 15 | L20: =IFERROR(INDIRECT(ADDRESS(ROW()+15,10,1,TRUE,L$4)),"") -> Y | M20: =IFERROR(INDIRECT(ADDRESS(ROW()+15,10,1,TRUE,M$4)),"") -> Y | N20: =IFERROR(INDIRECT(ADDRESS(ROW()+15,10,1,TRUE,N$4)),"") -> Y | O20: =IFERROR(INDIRECT(ADDRESS(ROW()+15,10,1,TRUE,O$4)),"") -> Y | P20: =IFERROR(INDIRECT(ADDRESS(ROW()+15,10,1,TRUE,P$4)),"") -> Y | Q20: =IFERROR(INDIRECT(ADDRESS(ROW()+15,10,1,TRUE,Q$4)),"") -> N | R20: =IFERROR(INDIRECT(ADDRESS(ROW()+15,10,1,TRUE,R$4)),"") -> N | S20: =IFERROR(INDIRECT(ADDRESS(ROW()+15,10,1,TRUE,S$4)),"") -> N | ... AC20: =IFERROR(INDIRECT(ADDRESS(ROW()+15,10,1,TRUE,AC$4)),"") -> N
B21: U2-10 | C21: =ChkList!$B21 -> U-15 | D21: =ChkList!$C21 -> 사용자, 시스템 시작파일 및 환경파일 소유자 및 권한 설정 | E21: =ChkList!$D21 -> H | F21: =COUNTA($L21:INDIRECT(ADDRESS(ROW(),MATCH("",$4:$4,-1),1,1))) -> 18 | G21: =COUNTIF($L21:INDIRECT(ADDRESS(ROW(),MATCH("",$4:$4,-1),1,1)),"Y") -> 18 | H21: =COUNTIF($L21:INDIRECT(ADDRESS(ROW(),MATCH("",$4:$4,-1),1,1)),"N") -> 0 | I21: =COUNTIF($L21:INDIRECT(ADDRESS(ROW(),MATCH("",$4:$4,-1),1,1)),"N/A") -> 0 | J21: =VLOOKUP($E21,ChkList!$A$47:$B$49,2,FALSE)*($F21-$I21) -> 54 | K21: =VLOOKUP($E21,ChkList!$A$47:$B$49,2,FALSE)*$G21 -> 54 | L21: =IFERROR(INDIRECT(ADDRESS(ROW()+15,10,1,TRUE,L$4)),"") -> Y | M21: =IFERROR(INDIRECT(ADDRESS(ROW()+15,10,1,TRUE,M$4)),"") -> Y | N21: =IFERROR(INDIRECT(ADDRESS(ROW()+15,10,1,TRUE,N$4)),"") -> Y | O21: =IFERROR(INDIRECT(ADDRESS(ROW()+15,10,1,TRUE,O$4)),"") -> Y | P21: =IFERROR(INDIRECT(ADDRESS(ROW()+15,10,1,TRUE,P$4)),"") -> Y | Q21: =IFERROR(INDIRECT(ADDRESS(ROW()+15,10,1,TRUE,Q$4)),"") -> Y | R21: =IFERROR(INDIRECT(ADDRESS(ROW()+15,10,1,TRUE,R$4)),"") -> Y | S21: =IFERROR(INDIRECT(ADDRESS(ROW()+15,10,1,TRUE,S$4)),"") -> Y | ... AC21: =IFERROR(INDIRECT(ADDRESS(ROW()+15,10,1,TRUE,AC$4)),"") -> Y
B22: U2-11 | C22: =ChkList!$B22 -> U-16 | D22: =ChkList!$C22 -> world writable 파일 점검 | E22: =ChkList!$D22 -> H | F22: =COUNTA($L22:INDIRECT(ADDRESS(ROW(),MATCH("",$4:$4,-1),1,1))) -> 18 | G22: =COUNTIF($L22:INDIRECT(ADDRESS(ROW(),MATCH("",$4:$4,-1),1,1)),"Y") -> 16 | H22: =COUNTIF($L22:INDIRECT(ADDRESS(ROW(),MATCH("",$4:$4,-1),1,1)),"N") -> 2 | I22: =COUNTIF($L22:INDIRECT(ADDRESS(ROW(),MATCH("",$4:$4,-1),1,1)),"N/A") -> 0 | J22: =VLOOKUP($E22,ChkList!$A$47:$B$49,2,FALSE)*($F22-$I22) -> 54 | K22: =VLOOKUP($E22,ChkList!$A$47:$B$49,2,FALSE)*$G22 -> 48 | L22: =IFERROR(INDIRECT(ADDRESS(ROW()+15,10,1,TRUE,L$4)),"") -> Y | M22: =IFERROR(INDIRECT(ADDRESS(ROW()+15,10,1,TRUE,M$4)),"") -> Y | N22: =IFERROR(INDIRECT(ADDRESS(ROW()+15,10,1,TRUE,N$4)),"") -> Y | O22: =IFERROR(INDIRECT(ADDRESS(ROW()+15,10,1,TRUE,O$4)),"") -> N | P22: =IFERROR(INDIRECT(ADDRESS(ROW()+15,10,1,TRUE,P$4)),"") -> N | Q22: =IFERROR(INDIRECT(ADDRESS(ROW()+15,10,1,TRUE,Q$4)),"") -> Y | R22: =IFERROR(INDIRECT(ADDRESS(ROW()+15,10,1,TRUE,R$4)),"") -> Y | S22: =IFERROR(INDIRECT(ADDRESS(ROW()+15,10,1,TRUE,S$4)),"") -> Y | ... AC22: =IFERROR(INDIRECT(ADDRESS(ROW()+15,10,1,TRUE,AC$4)),"") -> Y
B23: U2-13 | C23: =ChkList!$B23 -> U-17 | D23: =ChkList!$C23 -> $HOME/.rhosts, hosts.equiv 사용 금지 | E23: =ChkList!$D23 -> H | F23: =COUNTA($L23:INDIRECT(ADDRESS(ROW(),MATCH("",$4:$4,-1),1,1))) -> 18 | G23: =COUNTIF($L23:INDIRECT(ADDRESS(ROW(),MATCH("",$4:$4,-1),1,1)),"Y") -> 18 | H23: =COUNTIF($L23:INDIRECT(ADDRESS(ROW(),MATCH("",$4:$4,-1),1,1)),"N") -> 0 | I23: =COUNTIF($L23:INDIRECT(ADDRESS(ROW(),MATCH("",$4:$4,-1),1,1)),"N/A") -> 0 | J23: =VLOOKUP($E23,ChkList!$A$47:$B$49,2,FALSE)*($F23-$I23) -> 54 | K23: =VLOOKUP($E23,ChkList!$A$47:$B$49,2,FALSE)*$G23 -> 54 | L23: =IFERROR(INDIRECT(ADDRESS(ROW()+15,10,1,TRUE,L$4)),"") -> Y | M23: =IFERROR(INDIRECT(ADDRESS(ROW()+15,10,1,TRUE,M$4)),"") -> Y | N23: =IFERROR(INDIRECT(ADDRESS(ROW()+15,10,1,TRUE,N$4)),"") -> Y | O23: =IFERROR(INDIRECT(ADDRESS(ROW()+15,10,1,TRUE,O$4)),"") -> Y | P23: =IFERROR(INDIRECT(ADDRESS(ROW()+15,10,1,TRUE,P$4)),"") -> Y | Q23: =IFERROR(INDIRECT(ADDRESS(ROW()+15,10,1,TRUE,Q$4)),"") -> Y | R23: =IFERROR(INDIRECT(ADDRESS(ROW()+15,10,1,TRUE,R$4)),"") -> Y | S23: =IFERROR(INDIRECT(ADDRESS(ROW()+15,10,1,TRUE,S$4)),"") -> Y | ... AC23: =IFERROR(INDIRECT(ADDRESS(ROW()+15,10,1,TRUE,AC$4)),"") -> Y
... B25: U2-15 | C25: =ChkList!$B25 -> U-19 | D25: =ChkList!$C25 -> cron 파일 소유자 및 권한 설정 | E25: =ChkList!$D25 -> H | F25: =COUNTA($L25:INDIRECT(ADDRESS(ROW(),MATCH("",$4:$4,-1),1,1))) -> 18 | G25: =COUNTIF($L25:INDIRECT(ADDRESS(ROW(),MATCH("",$4:$4,-1),1,1)),"Y") -> 18 | H25: =COUNTIF($L25:INDIRECT(ADDRESS(ROW(),MATCH("",$4:$4,-1),1,1)),"N") -> 0 | I25: =COUNTIF($L25:INDIRECT(ADDRESS(ROW(),MATCH("",$4:$4,-1),1,1)),"N/A") -> 0 | J25: =VLOOKUP($E25,ChkList!$A$47:$B$49,2,FALSE)*($F25-$I25) -> 54 | K25: =VLOOKUP($E25,ChkList!$A$47:$B$49,2,FALSE)*$G25 -> 54 | L25: =IFERROR(INDIRECT(ADDRESS(ROW()+15,10,1,TRUE,L$4)),"") -> Y | M25: =IFERROR(INDIRECT(ADDRESS(ROW()+15,10,1,TRUE,M$4)),"") -> Y | N25: =IFERROR(INDIRECT(ADDRESS(ROW()+15,10,1,TRUE,N$4)),"") -> Y | O25: =IFERROR(INDIRECT(ADDRESS(ROW()+15,10,1,TRUE,O$4)),"") -> Y | P25: =IFERROR(INDIRECT(ADDRESS(ROW()+15,10,1,TRUE,P$4)),"") -> Y | Q25: =IFERROR(INDIRECT(ADDRESS(ROW()+15,10,1,TRUE,Q$4)),"") -> Y | R25: =IFERROR(INDIRECT(ADDRESS(ROW()+15,10,1,TRUE,R$4)),"") -> Y | S25: =IFERROR(INDIRECT(ADDRESS(ROW()+15,10,1,TRUE,S$4)),"") -> Y | ... AC25: =IFERROR(INDIRECT(ADDRESS(ROW()+15,10,1,TRUE,AC$4)),"") -> Y
A26: =ChkList!$A$26 -> U3 | C26: =VLOOKUP($A26,ChkList!$A$5:$B$44,2,FALSE) -> 서비스 관리
B27: U3-01 | C27: =ChkList!$B27 -> U-20 | D27: =ChkList!$C27 -> Finger 서비스 비활성화 | E27: =ChkList!$D27 -> H | F27: =COUNTA($L27:INDIRECT(ADDRESS(ROW(),MATCH("",$4:$4,-1),1,1))) -> 18 | G27: =COUNTIF($L27:INDIRECT(ADDRESS(ROW(),MATCH("",$4:$4,-1),1,1)),"Y") -> 18 | H27: =COUNTIF($L27:INDIRECT(ADDRESS(ROW(),MATCH("",$4:$4,-1),1,1)),"N") -> 0 | I27: =COUNTIF($L27:INDIRECT(ADDRESS(ROW(),MATCH("",$4:$4,-1),1,1)),"N/A") -> 0 | J27: =VLOOKUP($E27,ChkList!$A$47:$B$49,2,FALSE)*($F27-$I27) -> 54 | K27: =VLOOKUP($E27,ChkList!$A$47:$B$49,2,FALSE)*$G27 -> 54 | L27: =IFERROR(INDIRECT(ADDRESS(ROW()+15,10,1,TRUE,L$4)),"") -> Y | M27: =IFERROR(INDIRECT(ADDRESS(ROW()+15,10,1,TRUE,M$4)),"") -> Y | N27: =IFERROR(INDIRECT(ADDRESS(ROW()+15,10,1,TRUE,N$4)),"") -> Y | O27: =IFERROR(INDIRECT(ADDRESS(ROW()+15,10,1,TRUE,O$4)),"") -> Y | P27: =IFERROR(INDIRECT(ADDRESS(ROW()+15,10,1,TRUE,P$4)),"") -> Y | Q27: =IFERROR(INDIRECT(ADDRESS(ROW()+15,10,1,TRUE,Q$4)),"") -> Y | R27: =IFERROR(INDIRECT(ADDRESS(ROW()+15,10,1,TRUE,R$4)),"") -> Y | S27: =IFERROR(INDIRECT(ADDRESS(ROW()+15,10,1,TRUE,S$4)),"") -> Y | ... AC27: =IFERROR(INDIRECT(ADDRESS(ROW()+15,10,1,TRUE,AC$4)),"") -> Y
B28: U3-02 | C28: =ChkList!$B28 -> U-21 | D28: =ChkList!$C28 -> Anonymous FTP 비활성화 | E28: =ChkList!$D28 -> H | F28: =COUNTA($L28:INDIRECT(ADDRESS(ROW(),MATCH("",$4:$4,-1),1,1))) -> 18 | G28: =COUNTIF($L28:INDIRECT(ADDRESS(ROW(),MATCH("",$4:$4,-1),1,1)),"Y") -> 17 | H28: =COUNTIF($L28:INDIRECT(ADDRESS(ROW(),MATCH("",$4:$4,-1),1,1)),"N") -> 1 | I28: =COUNTIF($L28:INDIRECT(ADDRESS(ROW(),MATCH("",$4:$4,-1),1,1)),"N/A") -> 0 | J28: =VLOOKUP($E28,ChkList!$A$47:$B$49,2,FALSE)*($F28-$I28) -> 54 | K28: =VLOOKUP($E28,ChkList!$A$47:$B$49,2,FALSE)*$G28 -> 51 | L28: =IFERROR(INDIRECT(ADDRESS(ROW()+15,10,1,TRUE,L$4)),"") -> Y | M28: =IFERROR(INDIRECT(ADDRESS(ROW()+15,10,1,TRUE,M$4)),"") -> Y | N28: =IFERROR(INDIRECT(ADDRESS(ROW()+15,10,1,TRUE,N$4)),"") -> N | O28: =IFERROR(INDIRECT(ADDRESS(ROW()+15,10,1,TRUE,O$4)),"") -> Y | P28: =IFERROR(INDIRECT(ADDRESS(ROW()+15,10,1,TRUE,P$4)),"") -> Y | Q28: =IFERROR(INDIRECT(ADDRESS(ROW()+15,10,1,TRUE,Q$4)),"") -> Y | R28: =IFERROR(INDIRECT(ADDRESS(ROW()+15,10,1,TRUE,R$4)),"") -> Y | S28: =IFERROR(INDIRECT(ADDRESS(ROW()+15,10,1,TRUE,S$4)),"") -> Y | ... AC28: =IFERROR(INDIRECT(ADDRESS(ROW()+15,10,1,TRUE,AC$4)),"") -> Y
B29: U3-03 | C29: =ChkList!$B29 -> U-22 | D29: =ChkList!$C29 -> r 계열 서비스 비활성화 | E29: =ChkList!$D29 -> H | F29: =COUNTA($L29:INDIRECT(ADDRESS(ROW(),MATCH("",$4:$4,-1),1,1))) -> 18 | G29: =COUNTIF($L29:INDIRECT(ADDRESS(ROW(),MATCH("",$4:$4,-1),1,1)),"Y") -> 18 | H29: =COUNTIF($L29:INDIRECT(ADDRESS(ROW(),MATCH("",$4:$4,-1),1,1)),"N") -> 0 | I29: =COUNTIF($L29:INDIRECT(ADDRESS(ROW(),MATCH("",$4:$4,-1),1,1)),"N/A") -> 0 | J29: =VLOOKUP($E29,ChkList!$A$47:$B$49,2,FALSE)*($F29-$I29) -> 54 | K29: =VLOOKUP($E29,ChkList!$A$47:$B$49,2,FALSE)*$G29 -> 54 | L29: =IFERROR(INDIRECT(ADDRESS(ROW()+15,10,1,TRUE,L$4)),"") -> Y | M29: =IFERROR(INDIRECT(ADDRESS(ROW()+15,10,1,TRUE,M$4)),"") -> Y | N29: =IFERROR(INDIRECT(ADDRESS(ROW()+15,10,1,TRUE,N$4)),"") -> Y | O29: =IFERROR(INDIRECT(ADDRESS(ROW()+15,10,1,TRUE,O$4)),"") -> Y | P29: =IFERROR(INDIRECT(ADDRESS(ROW()+15,10,1,TRUE,P$4)),"") -> Y | Q29: =IFERROR(INDIRECT(ADDRESS(ROW()+15,10,1,TRUE,Q$4)),"") -> Y | R29: =IFERROR(INDIRECT(ADDRESS(ROW()+15,10,1,TRUE,R$4)),"") -> Y | S29: =IFERROR(INDIRECT(ADDRESS(ROW()+15,10,1,TRUE,S$4)),"") -> Y | ... AC29: =IFERROR(INDIRECT(ADDRESS(ROW()+15,10,1,TRUE,AC$4)),"") -> Y
B30: U3-04 | C30: =ChkList!$B30 -> U-23 | D30: =ChkList!$C30 -> DoS 공격에 취약한 서비스 비활성화 | E30: =ChkList!$D30 -> H | F30: =COUNTA($L30:INDIRECT(ADDRESS(ROW(),MATCH("",$4:$4,-1),1,1))) -> 18 | G30: =COUNTIF($L30:INDIRECT(ADDRESS(ROW(),MATCH("",$4:$4,-1),1,1)),"Y") -> 18 | H30: =COUNTIF($L30:INDIRECT(ADDRESS(ROW(),MATCH("",$4:$4,-1),1,1)),"N") -> 0 | I30: =COUNTIF($L30:INDIRECT(ADDRESS(ROW(),MATCH("",$4:$4,-1),1,1)),"N/A") -> 0 | J30: =VLOOKUP($E30,ChkList!$A$47:$B$49,2,FALSE)*($F30-$I30) -> 54 | K30: =VLOOKUP($E30,ChkList!$A$47:$B$49,2,FALSE)*$G30 -> 54 | L30: =IFERROR(INDIRECT(ADDRESS(ROW()+15,10,1,TRUE,L$4)),"") -> Y | M30: =IFERROR(INDIRECT(ADDRESS(ROW()+15,10,1,TRUE,M$4)),"") -> Y | N30: =IFERROR(INDIRECT(ADDRESS(ROW()+15,10,1,TRUE,N$4)),"") -> Y | O30: =IFERROR(INDIRECT(ADDRESS(ROW()+15,10,1,TRUE,O$4)),"") -> Y | P30: =IFERROR(INDIRECT(ADDRESS(ROW()+15,10,1,TRUE,P$4)),"") -> Y | Q30: =IFERROR(INDIRECT(ADDRESS(ROW()+15,10,1,TRUE,Q$4)),"") -> Y | R30: =IFERROR(INDIRECT(ADDRESS(ROW()+15,10,1,TRUE,R$4)),"") -> Y | S30: =IFERROR(INDIRECT(ADDRESS(ROW()+15,10,1,TRUE,S$4)),"") -> Y | ... AC30: =IFERROR(INDIRECT(ADDRESS(ROW()+15,10,1,TRUE,AC$4)),"") -> Y
B31: U3-05 | C31: =ChkList!$B31 -> U-24 | D31: =ChkList!$C31 -> NFS 서비스 비활성화 | E31: =ChkList!$D31 -> H | F31: =COUNTA($L31:INDIRECT(ADDRESS(ROW(),MATCH("",$4:$4,-1),1,1))) -> 18 | G31: =COUNTIF($L31:INDIRECT(ADDRESS(ROW(),MATCH("",$4:$4,-1),1,1)),"Y") -> 18 | H31: =COUNTIF($L31:INDIRECT(ADDRESS(ROW(),MATCH("",$4:$4,-1),1,1)),"N") -> 0 | I31: =COUNTIF($L31:INDIRECT(ADDRESS(ROW(),MATCH("",$4:$4,-1),1,1)),"N/A") -> 0 | J31: =VLOOKUP($E31,ChkList!$A$47:$B$49,2,FALSE)*($F31-$I31) -> 54 | K31: =VLOOKUP($E31,ChkList!$A$47:$B$49,2,FALSE)*$G31 -> 54 | L31: =IFERROR(INDIRECT(ADDRESS(ROW()+15,10,1,TRUE,L$4)),"") -> Y | M31: =IFERROR(INDIRECT(ADDRESS(ROW()+15,10,1,TRUE,M$4)),"") -> Y | N31: =IFERROR(INDIRECT(ADDRESS(ROW()+15,10,1,TRUE,N$4)),"") -> Y | O31: =IFERROR(INDIRECT(ADDRESS(ROW()+15,10,1,TRUE,O$4)),"") -> Y | P31: =IFERROR(INDIRECT(ADDRESS(ROW()+15,10,1,TRUE,P$4)),"") -> Y | Q31: =IFERROR(INDIRECT(ADDRESS(ROW()+15,10,1,TRUE,Q$4)),"") -> Y | R31: =IFERROR(INDIRECT(ADDRESS(ROW()+15,10,1,TRUE,R$4)),"") -> Y | S31: =IFERROR(INDIRECT(ADDRESS(ROW()+15,10,1,TRUE,S$4)),"") -> Y | ... AC31: =IFERROR(INDIRECT(ADDRESS(ROW()+15,10,1,TRUE,AC$4)),"") -> Y
B32: U3-06 | C32: =ChkList!$B32 -> U-25 | D32: =ChkList!$C32 -> NFS 접근통제 | E32: =ChkList!$D32 -> H | F32: =COUNTA($L32:INDIRECT(ADDRESS(ROW(),MATCH("",$4:$4,-1),1,1))) -> 18 | G32: =COUNTIF($L32:INDIRECT(ADDRESS(ROW(),MATCH("",$4:$4,-1),1,1)),"Y") -> 18 | H32: =COUNTIF($L32:INDIRECT(ADDRESS(ROW(),MATCH("",$4:$4,-1),1,1)),"N") -> 0 | I32: =COUNTIF($L32:INDIRECT(ADDRESS(ROW(),MATCH("",$4:$4,-1),1,1)),"N/A") -> 0 | J32: =VLOOKUP($E32,ChkList!$A$47:$B$49,2,FALSE)*($F32-$I32) -> 54 | K32: =VLOOKUP($E32,ChkList!$A$47:$B$49,2,FALSE)*$G32 -> 54 | L32: =IFERROR(INDIRECT(ADDRESS(ROW()+15,10,1,TRUE,L$4)),"") -> Y | M32: =IFERROR(INDIRECT(ADDRESS(ROW()+15,10,1,TRUE,M$4)),"") -> Y | N32: =IFERROR(INDIRECT(ADDRESS(ROW()+15,10,1,TRUE,N$4)),"") -> Y | O32: =IFERROR(INDIRECT(ADDRESS(ROW()+15,10,1,TRUE,O$4)),"") -> Y | P32: =IFERROR(INDIRECT(ADDRESS(ROW()+15,10,1,TRUE,P$4)),"") -> Y | Q32: =IFERROR(INDIRECT(ADDRESS(ROW()+15,10,1,TRUE,Q$4)),"") -> Y | R32: =IFERROR(INDIRECT(ADDRESS(ROW()+15,10,1,TRUE,R$4)),"") -> Y | S32: =IFERROR(INDIRECT(ADDRESS(ROW()+15,10,1,TRUE,S$4)),"") -> Y | ... AC32: =IFERROR(INDIRECT(ADDRESS(ROW()+15,10,1,TRUE,AC$4)),"") -> Y
B33: U3-07 | C33: =ChkList!$B33 -> U-26 | D33: =ChkList!$C33 -> automountd 제거 | E33: =ChkList!$D33 -> H | F33: =COUNTA($L33:INDIRECT(ADDRESS(ROW(),MATCH("",$4:$4,-1),1,1))) -> 18 | G33: =COUNTIF($L33:INDIRECT(ADDRESS(ROW(),MATCH("",$4:$4,-1),1,1)),"Y") -> 18 | H33: =COUNTIF($L33:INDIRECT(ADDRESS(ROW(),MATCH("",$4:$4,-1),1,1)),"N") -> 0 | I33: =COUNTIF($L33:INDIRECT(ADDRESS(ROW(),MATCH("",$4:$4,-1),1,1)),"N/A") -> 0 | J33: =VLOOKUP($E33,ChkList!$A$47:$B$49,2,FALSE)*($F33-$I33) -> 54 | K33: =VLOOKUP($E33,ChkList!$A$47:$B$49,2,FALSE)*$G33 -> 54 | L33: =IFERROR(INDIRECT(ADDRESS(ROW()+15,10,1,TRUE,L$4)),"") -> Y | M33: =IFERROR(INDIRECT(ADDRESS(ROW()+15,10,1,TRUE,M$4)),"") -> Y | N33: =IFERROR(INDIRECT(ADDRESS(ROW()+15,10,1,TRUE,N$4)),"") -> Y | O33: =IFERROR(INDIRECT(ADDRESS(ROW()+15,10,1,TRUE,O$4)),"") -> Y | P33: =IFERROR(INDIRECT(ADDRESS(ROW()+15,10,1,TRUE,P$4)),"") -> Y | Q33: =IFERROR(INDIRECT(ADDRESS(ROW()+15,10,1,TRUE,Q$4)),"") -> Y | R33: =IFERROR(INDIRECT(ADDRESS(ROW()+15,10,1,TRUE,R$4)),"") -> Y | S33: =IFERROR(INDIRECT(ADDRESS(ROW()+15,10,1,TRUE,S$4)),"") -> Y | ... AC33: =IFERROR(INDIRECT(ADDRESS(ROW()+15,10,1,TRUE,AC$4)),"") -> Y
B34: U3-08 | C34: =ChkList!$B34 -> U-27 | D34: =ChkList!$C34 -> RPC 서비스 확인 | E34: =ChkList!$D34 -> H | F34: =COUNTA($L34:INDIRECT(ADDRESS(ROW(),MATCH("",$4:$4,-1),1,1))) -> 18 | G34: =COUNTIF($L34:INDIRECT(ADDRESS(ROW(),MATCH("",$4:$4,-1),1,1)),"Y") -> 18 | H34: =COUNTIF($L34:INDIRECT(ADDRESS(ROW(),MATCH("",$4:$4,-1),1,1)),"N") -> 0 | I34: =COUNTIF($L34:INDIRECT(ADDRESS(ROW(),MATCH("",$4:$4,-1),1,1)),"N/A") -> 0 | J34: =VLOOKUP($E34,ChkList!$A$47:$B$49,2,FALSE)*($F34-$I34) -> 54 | K34: =VLOOKUP($E34,ChkList!$A$47:$B$49,2,FALSE)*$G34 -> 54 | L34: =IFERROR(INDIRECT(ADDRESS(ROW()+15,10,1,TRUE,L$4)),"") -> Y | M34: =IFERROR(INDIRECT(ADDRESS(ROW()+15,10,1,TRUE,M$4)),"") -> Y | N34: =IFERROR(INDIRECT(ADDRESS(ROW()+15,10,1,TRUE,N$4)),"") -> Y | O34: =IFERROR(INDIRECT(ADDRESS(ROW()+15,10,1,TRUE,O$4)),"") -> Y | P34: =IFERROR(INDIRECT(ADDRESS(ROW()+15,10,1,TRUE,P$4)),"") -> Y | Q34: =IFERROR(INDIRECT(ADDRESS(ROW()+15,10,1,TRUE,Q$4)),"") -> Y | R34: =IFERROR(INDIRECT(ADDRESS(ROW()+15,10,1,TRUE,R$4)),"") -> Y | S34: =IFERROR(INDIRECT(ADDRESS(ROW()+15,10,1,TRUE,S$4)),"") -> Y | ... AC34: =IFERROR(INDIRECT(ADDRESS(ROW()+15,10,1,TRUE,AC$4)),"") -> Y
B35: U3-09 | C35: =ChkList!$B35 -> U-28 | D35: =ChkList!$C35 -> NIS, NIS+ 점검 | E35: =ChkList!$D35 -> H | F35: =COUNTA($L35:INDIRECT(ADDRESS(ROW(),MATCH("",$4:$4,-1),1,1))) -> 18 | G35: =COUNTIF($L35:INDIRECT(ADDRESS(ROW(),MATCH("",$4:$4,-1),1,1)),"Y") -> 18 | H35: =COUNTIF($L35:INDIRECT(ADDRESS(ROW(),MATCH("",$4:$4,-1),1,1)),"N") -> 0 | I35: =COUNTIF($L35:INDIRECT(ADDRESS(ROW(),MATCH("",$4:$4,-1),1,1)),"N/A") -> 0 | J35: =VLOOKUP($E35,ChkList!$A$47:$B$49,2,FALSE)*($F35-$I35) -> 54 | K35: =VLOOKUP($E35,ChkList!$A$47:$B$49,2,FALSE)*$G35 -> 54 | L35: =IFERROR(INDIRECT(ADDRESS(ROW()+15,10,1,TRUE,L$4)),"") -> Y | M35: =IFERROR(INDIRECT(ADDRESS(ROW()+15,10,1,TRUE,M$4)),"") -> Y | N35: =IFERROR(INDIRECT(ADDRESS(ROW()+15,10,1,TRUE,N$4)),"") -> Y | O35: =IFERROR(INDIRECT(ADDRESS(ROW()+15,10,1,TRUE,O$4)),"") -> Y | P35: =IFERROR(INDIRECT(ADDRESS(ROW()+15,10,1,TRUE,P$4)),"") -> Y | Q35: =IFERROR(INDIRECT(ADDRESS(ROW()+15,10,1,TRUE,Q$4)),"") -> Y | R35: =IFERROR(INDIRECT(ADDRESS(ROW()+15,10,1,TRUE,R$4)),"") -> Y | S35: =IFERROR(INDIRECT(ADDRESS(ROW()+15,10,1,TRUE,S$4)),"") -> Y | ... AC35: =IFERROR(INDIRECT(ADDRESS(ROW()+15,10,1,TRUE,AC$4)),"") -> Y
B36: U3-10 | C36: =ChkList!$B36 -> U-29 | D36: =ChkList!$C36 -> tftp, talk 서비스 비활성화 | E36: =ChkList!$D36 -> H | F36: =COUNTA($L36:INDIRECT(ADDRESS(ROW(),MATCH("",$4:$4,-1),1,1))) -> 18 | G36: =COUNTIF($L36:INDIRECT(ADDRESS(ROW(),MATCH("",$4:$4,-1),1,1)),"Y") -> 18 | H36: =COUNTIF($L36:INDIRECT(ADDRESS(ROW(),MATCH("",$4:$4,-1),1,1)),"N") -> 0 | I36: =COUNTIF($L36:INDIRECT(ADDRESS(ROW(),MATCH("",$4:$4,-1),1,1)),"N/A") -> 0 | J36: =VLOOKUP($E36,ChkList!$A$47:$B$49,2,FALSE)*($F36-$I36) -> 54 | K36: =VLOOKUP($E36,ChkList!$A$47:$B$49,2,FALSE)*$G36 -> 54 | L36: =IFERROR(INDIRECT(ADDRESS(ROW()+15,10,1,TRUE,L$4)),"") -> Y | M36: =IFERROR(INDIRECT(ADDRESS(ROW()+15,10,1,TRUE,M$4)),"") -> Y | N36: =IFERROR(INDIRECT(ADDRESS(ROW()+15,10,1,TRUE,N$4)),"") -> Y | O36: =IFERROR(INDIRECT(ADDRESS(ROW()+15,10,1,TRUE,O$4)),"") -> Y | P36: =IFERROR(INDIRECT(ADDRESS(ROW()+15,10,1,TRUE,P$4)),"") -> Y | Q36: =IFERROR(INDIRECT(ADDRESS(ROW()+15,10,1,TRUE,Q$4)),"") -> Y | R36: =IFERROR(INDIRECT(ADDRESS(ROW()+15,10,1,TRUE,R$4)),"") -> Y | S36: =IFERROR(INDIRECT(ADDRESS(ROW()+15,10,1,TRUE,S$4)),"") -> Y | ... AC36: =IFERROR(INDIRECT(ADDRESS(ROW()+15,10,1,TRUE,AC$4)),"") -> Y
B37: U3-11 | C37: =ChkList!$B37 -> U-30 | D37: =ChkList!$C37 -> Sendmail 버전 점검 | E37: =ChkList!$D37 -> H | F37: =COUNTA($L37:INDIRECT(ADDRESS(ROW(),MATCH("",$4:$4,-1),1,1))) -> 18 | G37: =COUNTIF($L37:INDIRECT(ADDRESS(ROW(),MATCH("",$4:$4,-1),1,1)),"Y") -> 18 | H37: =COUNTIF($L37:INDIRECT(ADDRESS(ROW(),MATCH("",$4:$4,-1),1,1)),"N") -> 0 | I37: =COUNTIF($L37:INDIRECT(ADDRESS(ROW(),MATCH("",$4:$4,-1),1,1)),"N/A") -> 0 | J37: =VLOOKUP($E37,ChkList!$A$47:$B$49,2,FALSE)*($F37-$I37) -> 54 | K37: =VLOOKUP($E37,ChkList!$A$47:$B$49,2,FALSE)*$G37 -> 54 | L37: =IFERROR(INDIRECT(ADDRESS(ROW()+15,10,1,TRUE,L$4)),"") -> Y | M37: =IFERROR(INDIRECT(ADDRESS(ROW()+15,10,1,TRUE,M$4)),"") -> Y | N37: =IFERROR(INDIRECT(ADDRESS(ROW()+15,10,1,TRUE,N$4)),"") -> Y | O37: =IFERROR(INDIRECT(ADDRESS(ROW()+15,10,1,TRUE,O$4)),"") -> Y | P37: =IFERROR(INDIRECT(ADDRESS(ROW()+15,10,1,TRUE,P$4)),"") -> Y | Q37: =IFERROR(INDIRECT(ADDRESS(ROW()+15,10,1,TRUE,Q$4)),"") -> Y | R37: =IFERROR(INDIRECT(ADDRESS(ROW()+15,10,1,TRUE,R$4)),"") -> Y | S37: =IFERROR(INDIRECT(ADDRESS(ROW()+15,10,1,TRUE,S$4)),"") -> Y | ... AC37: =IFERROR(INDIRECT(ADDRESS(ROW()+15,10,1,TRUE,AC$4)),"") -> Y
B38: U3-12 | C38: =ChkList!$B38 -> U-31 | D38: =ChkList!$C38 -> 스팸 메일 릴레이 제한 | E38: =ChkList!$D38 -> H | F38: =COUNTA($L38:INDIRECT(ADDRESS(ROW(),MATCH("",$4:$4,-1),1,1))) -> 18 | G38: =COUNTIF($L38:INDIRECT(ADDRESS(ROW(),MATCH("",$4:$4,-1),1,1)),"Y") -> 18 | H38: =COUNTIF($L38:INDIRECT(ADDRESS(ROW(),MATCH("",$4:$4,-1),1,1)),"N") -> 0 | I38: =COUNTIF($L38:INDIRECT(ADDRESS(ROW(),MATCH("",$4:$4,-1),1,1)),"N/A") -> 0 | J38: =VLOOKUP($E38,ChkList!$A$47:$B$49,2,FALSE)*($F38-$I38) -> 54 | K38: =VLOOKUP($E38,ChkList!$A$47:$B$49,2,FALSE)*$G38 -> 54 | L38: =IFERROR(INDIRECT(ADDRESS(ROW()+15,10,1,TRUE,L$4)),"") -> Y | M38: =IFERROR(INDIRECT(ADDRESS(ROW()+15,10,1,TRUE,M$4)),"") -> Y | N38: =IFERROR(INDIRECT(ADDRESS(ROW()+15,10,1,TRUE,N$4)),"") -> Y | O38: =IFERROR(INDIRECT(ADDRESS(ROW()+15,10,1,TRUE,O$4)),"") -> Y | P38: =IFERROR(INDIRECT(ADDRESS(ROW()+15,10,1,TRUE,P$4)),"") -> Y | Q38: =IFERROR(INDIRECT(ADDRESS(ROW()+15,10,1,TRUE,Q$4)),"") -> Y | R38: =IFERROR(INDIRECT(ADDRESS(ROW()+15,10,1,TRUE,R$4)),"") -> Y | S38: =IFERROR(INDIRECT(ADDRESS(ROW()+15,10,1,TRUE,S$4)),"") -> Y | ... AC38: =IFERROR(INDIRECT(ADDRESS(ROW()+15,10,1,TRUE,AC$4)),"") -> Y
